Workbook

Sheet Summary_FY
A1: อัตราส่วนรายปี FY2568 — ฐาน CFA (=สูตรสด อ้าง FY_Inputs)
A2: อัตราส่วน | B2: ASIA | C2: CENTEL | D2: DUSIT | E2: ERW | F2: MANRIN | G2: MINT | H2: OHTL | I2: SHANG | J2: SHR | K2: VRANDA
A3: NPM (%) | B3: =IFERROR(FY_Inputs!B6/FY_Inputs!B3,"") | C3: =IFERROR(FY_Inputs!C6/FY_Inputs!C3,"") | D3: =IFERROR(FY_Inputs!D6/FY_Inputs!D3,"") | E3: =IFERROR(FY_Inputs!E6/FY_Inputs!E3,"") | F3: =IFERROR(FY_Inputs!F6/FY_Inputs!F3,"") | G3: =IFERROR(FY_Inputs!G6/FY_Inputs!G3,"") | H3: =IFERROR(FY_Inputs!H6/FY_Inputs!H3,"") | I3: =IFERROR(FY_Inputs!I6/FY_Inputs!I3,"") | ... K3: =IFERROR(FY_Inputs!K6/FY_Inputs!K3,"")
A4: Gross Margin (%) | B4: =IFERROR(((FY_Inputs!B3-FY_Inputs!B4)-FY_Inputs!B5)/(FY_Inputs!B3-FY_Inputs!B4),"") | C4: =IFERROR(((FY_Inputs!C3-FY_Inputs!C4)-FY_Inputs!C5)/(FY_Inputs!C3-FY_Inputs!C4),"") | D4: =IFERROR(((FY_Inputs!D3-FY_Inputs!D4)-FY_Inputs!D5)/(FY_Inputs!D3-FY_Inputs!D4),"") | E4: =IFERROR(((FY_Inputs!E3-FY_Inputs!E4)-FY_Inputs!E5)/(FY_Inputs!E3-FY_Inputs!E4),"") | F4: =IFERROR(((FY_Inputs!F3-FY_Inputs!F4)-FY_Inputs!F5)/(FY_Inputs!F3-FY_Inputs!F4),"") | G4: =IFERROR(((FY_Inputs!G3-FY_Inputs!G4)-FY_Inputs!G5)/(FY_Inputs!G3-FY_Inputs!G4),"") | H4: =IFERROR(((FY_Inputs!H3-FY_Inputs!H4)-FY_Inputs!H5)/(FY_Inputs!H3-FY_Inputs!H4),"") | I4: =IFERROR(((FY_Inputs!I3-FY_Inputs!I4)-FY_Inputs!I5)/(FY_Inputs!I3-FY_Inputs!I4),"") | ... K4: =IFERROR(((FY_Inputs!K3-FY_Inputs!K4)-FY_Inputs!K5)/(FY_Inputs!K3-FY_Inputs!K4),"")
A5: ROA (%) | B5: =IFERROR(FY_Inputs!B6/((FY_Inputs!B14+FY_Inputs!B15)/2),"") | C5: =IFERROR(FY_Inputs!C6/((FY_Inputs!C14+FY_Inputs!C15)/2),"") | D5: =IFERROR(FY_Inputs!D6/((FY_Inputs!D14+FY_Inputs!D15)/2),"") | E5: =IFERROR(FY_Inputs!E6/((FY_Inputs!E14+FY_Inputs!E15)/2),"") | F5: =IFERROR(FY_Inputs!F6/((FY_Inputs!F14+FY_Inputs!F15)/2),"") | G5: =IFERROR(FY_Inputs!G6/((FY_Inputs!G14+FY_Inputs!G15)/2),"") | H5: =IFERROR(FY_Inputs!H6/((FY_Inputs!H14+FY_Inputs!H15)/2),"") | I5: =IFERROR(FY_Inputs!I6/((FY_Inputs!I14+FY_Inputs!I15)/2),"") | ... K5: =IFERROR(FY_Inputs!K6/((FY_Inputs!K14+FY_Inputs!K15)/2),"")
A6: ROE รวม (%) | B6: =IFERROR(FY_Inputs!B6/((FY_Inputs!B16+FY_Inputs!B17)/2),"") | C6: =IFERROR(FY_Inputs!C6/((FY_Inputs!C16+FY_Inputs!C17)/2),"") | D6: =IFERROR(FY_Inputs!D6/((FY_Inputs!D16+FY_Inputs!D17)/2),"") | E6: =IFERROR(FY_Inputs!E6/((FY_Inputs!E16+FY_Inputs!E17)/2),"") | F6: =IFERROR(FY_Inputs!F6/((FY_Inputs!F16+FY_Inputs!F17)/2),"") | G6: =IFERROR(FY_Inputs!G6/((FY_Inputs!G16+FY_Inputs!G17)/2),"") | H6: =IFERROR(FY_Inputs!H6/((FY_Inputs!H16+FY_Inputs!H17)/2),"") | I6: =IFERROR(FY_Inputs!I6/((FY_Inputs!I16+FY_Inputs!I17)/2),"") | ... K6: =IFERROR(FY_Inputs!K6/((FY_Inputs!K16+FY_Inputs!K17)/2),"")
A7: ROE ส่วนแม่ (%) | B7: =IFERROR(FY_Inputs!B7/((FY_Inputs!B16+FY_Inputs!B17)/2),"") | C7: =IFERROR(FY_Inputs!C7/((FY_Inputs!C16+FY_Inputs!C17)/2),"") | D7: =IFERROR(FY_Inputs!D7/((FY_Inputs!D16+FY_Inputs!D17)/2),"") | E7: =IFERROR(FY_Inputs!E7/((FY_Inputs!E16+FY_Inputs!E17)/2),"") | F7: =IFERROR(FY_Inputs!F7/((FY_Inputs!F16+FY_Inputs!F17)/2),"") | G7: =IFERROR(FY_Inputs!G7/((FY_Inputs!G16+FY_Inputs!G17)/2),"") | H7: =IFERROR(FY_Inputs!H7/((FY_Inputs!H16+FY_Inputs!H17)/2),"") | I7: =IFERROR(FY_Inputs!I7/((FY_Inputs!I16+FY_Inputs!I17)/2),"") | ... K7: =IFERROR(FY_Inputs!K7/((FY_Inputs!K16+FY_Inputs!K17)/2),"")
A8: DSO (วัน) | B8: =IFERROR(((FY_Inputs!B8+FY_Inputs!B9)/2)/FY_Inputs!B3*365,"") | C8: =IFERROR(((FY_Inputs!C8+FY_Inputs!C9)/2)/FY_Inputs!C3*365,"") | D8: =IFERROR(((FY_Inputs!D8+FY_Inputs!D9)/2)/FY_Inputs!D3*365,"") | E8: =IFERROR(((FY_Inputs!E8+FY_Inputs!E9)/2)/FY_Inputs!E3*365,"") | F8: =IFERROR(((FY_Inputs!F8+FY_Inputs!F9)/2)/FY_Inputs!F3*365,"") | G8: =IFERROR(((FY_Inputs!G8+FY_Inputs!G9)/2)/FY_Inputs!G3*365,"") | H8: =IFERROR(((FY_Inputs!H8+FY_Inputs!H9)/2)/FY_Inputs!H3*365,"") | I8: =IFERROR(((FY_Inputs!I8+FY_Inputs!I9)/2)/FY_Inputs!I3*365,"") | ... K8: =IFERROR(((FY_Inputs!K8+FY_Inputs!K9)/2)/FY_Inputs!K3*365,"")
A9: DIO (วัน) | B9: =IFERROR(((FY_Inputs!B10+FY_Inputs!B11)/2)/FY_Inputs!B5*365,"") | C9: =IFERROR(((FY_Inputs!C10+FY_Inputs!C11)/2)/FY_Inputs!C5*365,"") | D9: =IFERROR(((FY_Inputs!D10+FY_Inputs!D11)/2)/FY_Inputs!D5*365,"") | E9: =IFERROR(((FY_Inputs!E10+FY_Inputs!E11)/2)/FY_Inputs!E5*365,"") | F9: =IFERROR(((FY_Inputs!F10+FY_Inputs!F11)/2)/FY_Inputs!F5*365,"") | G9: =IFERROR(((FY_Inputs!G10+FY_Inputs!G11)/2)/FY_Inputs!G5*365,"") | H9: =IFERROR(((FY_Inputs!H10+FY_Inputs!H11)/2)/FY_Inputs!H5*365,"") | I9: =IFERROR(((FY_Inputs!I10+FY_Inputs!I11)/2)/FY_Inputs!I5*365,"") | ... K9: =IFERROR(((FY_Inputs!K10+FY_Inputs!K11)/2)/FY_Inputs!K5*365,"")
A10: DPO (วัน) | B10: =IFERROR(((FY_Inputs!B12+FY_Inputs!B13)/2)/FY_Inputs!B5*365,"") | C10: =IFERROR(((FY_Inputs!C12+FY_Inputs!C13)/2)/FY_Inputs!C5*365,"") | D10: =IFERROR(((FY_Inputs!D12+FY_Inputs!D13)/2)/FY_Inputs!D5*365,"") | E10: =IFERROR(((FY_Inputs!E12+FY_Inputs!E13)/2)/FY_Inputs!E5*365,"") | F10: =IFERROR(((FY_Inputs!F12+FY_Inputs!F13)/2)/FY_Inputs!F5*365,"") | G10: =IFERROR(((FY_Inputs!G12+FY_Inputs!G13)/2)/FY_Inputs!G5*365,"") | H10: =IFERROR(((FY_Inputs!H12+FY_Inputs!H13)/2)/FY_Inputs!H5*365,"") | I10: =IFERROR(((FY_Inputs!I12+FY_Inputs!I13)/2)/FY_Inputs!I5*365,"") | ... K10: =IFERROR(((FY_Inputs!K12+FY_Inputs!K13)/2)/FY_Inputs!K5*365,"")
A11: CCC (วัน) | B11: =IFERROR(B8+B9-B10,"") | C11: =IFERROR(C8+C9-C10,"") | D11: =IFERROR(D8+D9-D10,"") | E11: =IFERROR(E8+E9-E10,"") | F11: =IFERROR(F8+F9-F10,"") | G11: =IFERROR(G8+G9-G10,"") | H11: =IFERROR(H8+H9-H10,"") | I11: =IFERROR(I8+I9-I10,"") | ... K11: =IFERROR(K8+K9-K10,"")
A12: D/E (เท่า) | B12: =IFERROR(FY_Inputs!B18/FY_Inputs!B17,"") | C12: =IFERROR(FY_Inputs!C18/FY_Inputs!C17,"") | D12: =IFERROR(FY_Inputs!D18/FY_Inputs!D17,"") | E12: =IFERROR(FY_Inputs!E18/FY_Inputs!E17,"") | F12: =IFERROR(FY_Inputs!F18/FY_Inputs!F17,"") | G12: =IFERROR(FY_Inputs!G18/FY_Inputs!G17,"") | H12: =IFERROR(FY_Inputs!H18/FY_Inputs!H17,"") | I12: =IFERROR(FY_Inputs!I18/FY_Inputs!I17,"") | ... K12: =IFERROR(FY_Inputs!K18/FY_Inputs!K17,"")

Sheet FY_Inputs
A1: ตัวเลขดิบรายปี FY2568 (ล้านบาท) — ช่องเหลืองแก้ได้
A2: รายการ | B2: ASIA | C2: CENTEL | D2: DUSIT | E2: ERW | F2: MANRIN | G2: MINT | H2: OHTL | I2: SHANG | J2: SHR | K2: VRANDA
A3: รายได้รวม (FY) | B3: 1364.564 | C3: 25050.93 | D3: 8923.997 | E3: 7937.392 | F3: 363.247 | G3: 165804.71 | H3: 2524.941 | I3: 2153.389 | J3: 10411.173 | K3: 1577.181
A4: รายได้อื่น (FY) | B4: 80.027 | C4: 1096.979 | D4: 1013.082 | E4: 25.178 | F4: 1.015 | G4: 4275.181 | H4: 2.68 | I4: 20.237 | J4: 111.837 | K4: 46.964
A5: ต้นทุนขาย (FY) | B5: 942.602 | C5: 13356.611 | D5: 5378.316 | E5: 3265.028 | F5: 213.736 | G5: 86221.785 | H5: 1332.588 | I5: 695.217 | J5: 6279.64 | K5: 866.224
A6: กำไรสุทธิ (รวมส่วนได้เสียไม่มีอำนาจควบคุม) | B6: -3.355 | C6: 1964.146 | D6: -470.835 | E6: 904.756 | F6: 39.818 | G6: 9839.333 | H6: 313.694 | I6: 240.904 | J6: -1586.048 | K6: 100.784
A7: กำไรสุทธิ (ส่วนของผู้ถือหุ้นบริษัทใหญ่) | B7: -1.129 | C7: 1992.902 | D7: -453.313 | E7: 838.085 | F7: 39.818 | G7: 9009.342 | H7: 313.694 | I7: 240.912 | J7: -1586.048 | K7: 100.784
A8: ลูกหนี้การค้า — ต้นปี | B8: 87.279 | C8: 1207.737 | D8: 1145.08 | E8: 222.438 | F8: 13.217 | G8: 13970.341 | H8: 84.202 | I8: 80.064 | J8: 475.753 | K8: 55.427
A9: ลูกหนี้การค้า — ปลายปี | B9: 90.573 | C9: 961.72 | D9: 1482.137 | E9: 232.438 | F9: 10.615 | G9: 15911.602 | H9: 107.373 | I9: 90.013 | J9: 406.258 | K9: 52.939
A10: สินค้าคงเหลือ — ต้นปี | B10: 46.247 | C10: 904.759 | D10: 130.736 | E10: 42.817 | F10: 1.626 | G10: 3917.636 | H10: 28.86 | I10: 28.732 | J10: 232.259 | K10: 16.851
A11: สินค้าคงเหลือ — ปลายปี | B11: 46.002 | C11: 868.216 | D11: 133.654 | E11: 40.396 | F11: 1.637 | G11: 3921.48 | H11: 36.342 | I11: 27.883 | J11: 244.432 | K11: 20.38
A12: เจ้าหนี้การค้า — ต้นปี | B12: 140.797 | C12: 4423.239 | D12: 1909.206 | E12: 266.009 | F12: 40.06 | G12: 24414.611 | H12: 374.801 | I12: 234.957 | J12: 975.128 | K12: 440.911
A13: เจ้าหนี้การค้า — ปลายปี | B13: 150.322 | C13: 3929.778 | D13: 2068.782 | E13: 257.323 | F13: 30.444 | G13: 25606.359 | H13: 598.642 | I13: 259.24 | J13: 1009.863 | K13: 238.739
A14: สินทรัพย์รวม — ต้นปี | B14: 10140.751 | C14: 60760.633 | D14: 38270.77 | E14: 26246.078 | F14: 691.668 | G14: 346844.93 | H14: 5742.7 | I14: 8067.434 | J14: 36325.359 | K14: 5614.758
... A18: หนี้สินรวม — ปลายปี | B18: 4423.187 | C18: 40113.547 | D18: 31460.24 | E18: 16672.762 | F18: 168.877 | G18: 260344.01 | H18: 3250.326 | I18: 752.882 | J18: 19630.194 | K18: 3875.886

Sheet Quarterly_Ratios
A1: ตัวชี้วัด | B1: Q1/2564 | C1: Q2/2564 | D1: Q3/2564 | E1: Q4/2564 | F1: Q1/2565 | G1: Q2/2565 | H1: Q3/2565 | I1: Q4/2565 | J1: Q1/2566 | K1: Q2/2566 | L1: Q3/2566 | M1: Q4/2566 | N1: Q1/2567 | O1: Q2/2567 | P1: Q3/2567 | Q1: Q4/2567 | R1: Q1/2568 | S1: Q2/2568 | T1: Q3/2568 | U1: Q4/2568
A2: ■ ASIA
A3: รายได้รวม (ล้านบาท) | B3: =IS_Flow!B3 | C3: =IS_Flow!C3 | D3: =IS_Flow!D3 | E3: =IS_Flow!E3 | F3: =IS_Flow!G3 | G3: =IS_Flow!H3 | H3: =IS_Flow!I3 | I3: =IS_Flow!J3 | J3: =IS_Flow!L3 | K3: =IS_Flow!M3 | L3: =IS_Flow!N3 | M3: =IS_Flow!O3 | N3: =IS_Flow!Q3 | O3: =IS_Flow!R3 | P3: =IS_Flow!S3 | Q3: =IS_Flow!T3 | R3: =IS_Flow!V3 | S3: =IS_Flow!W3 | T3: =IS_Flow!X3 | U3: =IS_Flow!Y3
A4: ต้นทุนขาย (ล้านบาท) | B4: =IS_Flow!B5 | C4: =IS_Flow!C5 | D4: =IS_Flow!D5 | E4: =IS_Flow!E5 | F4: =IS_Flow!G5 | G4: =IS_Flow!H5 | H4: =IS_Flow!I5 | I4: =IS_Flow!J5 | J4: =IS_Flow!L5 | K4: =IS_Flow!M5 | L4: =IS_Flow!N5 | M4: =IS_Flow!O5 | N4: =IS_Flow!Q5 | O4: =IS_Flow!R5 | P4: =IS_Flow!S5 | Q4: =IS_Flow!T5 | R4: =IS_Flow!V5 | S4: =IS_Flow!W5 | T4: =IS_Flow!X5 | U4: =IS_Flow!Y5
A5: กำไรสุทธิ (ล้านบาท) | B5: =IS_Flow!B6 | C5: =IS_Flow!C6 | D5: =IS_Flow!D6 | E5: =IS_Flow!E6 | F5: =IS_Flow!G6 | G5: =IS_Flow!H6 | H5: =IS_Flow!I6 | I5: =IS_Flow!J6 | J5: =IS_Flow!L6 | K5: =IS_Flow!M6 | L5: =IS_Flow!N6 | M5: =IS_Flow!O6 | N5: =IS_Flow!Q6 | O5: =IS_Flow!R6 | P5: =IS_Flow!S6 | Q5: =IS_Flow!T6 | R5: =IS_Flow!V6 | S5: =IS_Flow!W6 | T5: =IS_Flow!X6 | U5: =IS_Flow!Y6
A6: NPM (%) | B6: =IFERROR(IS_Flow!B6/IS_Flow!B3,"") | C6: =IFERROR(IS_Flow!C6/IS_Flow!C3,"") | D6: =IFERROR(IS_Flow!D6/IS_Flow!D3,"") | E6: =IFERROR(IS_Flow!E6/IS_Flow!E3,"") | F6: =IFERROR(IS_Flow!G6/IS_Flow!G3,"") | G6: =IFERROR(IS_Flow!H6/IS_Flow!H3,"") | H6: =IFERROR(IS_Flow!I6/IS_Flow!I3,"") | I6: =IFERROR(IS_Flow!J6/IS_Flow!J3,"") | J6: =IFERROR(IS_Flow!L6/IS_Flow!L3,"") | K6: =IFERROR(IS_Flow!M6/IS_Flow!M3,"") | L6: =IFERROR(IS_Flow!N6/IS_Flow!N3,"") | M6: =IFERROR(IS_Flow!O6/IS_Flow!O3,"") | N6: =IFERROR(IS_Flow!Q6/IS_Flow!Q3,"") | O6: =IFERROR(IS_Flow!R6/IS_Flow!R3,"") | P6: =IFERROR(IS_Flow!S6/IS_Flow!S3,"") | Q6: =IFERROR(IS_Flow!T6/IS_Flow!T3,"") | R6: =IFERROR(IS_Flow!V6/IS_Flow!V3,"") | S6: =IFERROR(IS_Flow!W6/IS_Flow!W3,"") | T6: =IFERROR(IS_Flow!X6/IS_Flow!X3,"") | U6: =IFERROR(IS_Flow!Y6/IS_Flow!Y3,"")
A7: Gross Margin (%) | B7: =IFERROR((IS_Flow!B3-IS_Flow!B4-IS_Flow!B5)/(IS_Flow!B3-IS_Flow!B4),"") | C7: =IFERROR((IS_Flow!C3-IS_Flow!C4-IS_Flow!C5)/(IS_Flow!C3-IS_Flow!C4),"") | D7: =IFERROR((IS_Flow!D3-IS_Flow!D4-IS_Flow!D5)/(IS_Flow!D3-IS_Flow!D4),"") | E7: =IFERROR((IS_Flow!E3-IS_Flow!E4-IS_Flow!E5)/(IS_Flow!E3-IS_Flow!E4),"") | F7: =IFERROR((IS_Flow!G3-IS_Flow!G4-IS_Flow!G5)/(IS_Flow!G3-IS_Flow!G4),"") | G7: =IFERROR((IS_Flow!H3-IS_Flow!H4-IS_Flow!H5)/(IS_Flow!H3-IS_Flow!H4),"") | H7: =IFERROR((IS_Flow!I3-IS_Flow!I4-IS_Flow!I5)/(IS_Flow!I3-IS_Flow!I4),"") | I7: =IFERROR((IS_Flow!J3-IS_Flow!J4-IS_Flow!J5)/(IS_Flow!J3-IS_Flow!J4),"") | J7: =IFERROR((IS_Flow!L3-IS_Flow!L4-IS_Flow!L5)/(IS_Flow!L3-IS_Flow!L4),"") | K7: =IFERROR((IS_Flow!M3-IS_Flow!M4-IS_Flow!M5)/(IS_Flow!M3-IS_Flow!M4),"") | L7: =IFERROR((IS_Flow!N3-IS_Flow!N4-IS_Flow!N5)/(IS_Flow!N3-IS_Flow!N4),"") | M7: =IFERROR((IS_Flow!O3-IS_Flow!O4-IS_Flow!O5)/(IS_Flow!O3-IS_Flow!O4),"") | N7: =IFERROR((IS_Flow!Q3-IS_Flow!Q4-IS_Flow!Q5)/(IS_Flow!Q3-IS_Flow!Q4),"") | O7: =IFERROR((IS_Flow!R3-IS_Flow!R4-IS_Flow!R5)/(IS_Flow!R3-IS_Flow!R4),"") | P7: =IFERROR((IS_Flow!S3-IS_Flow!S4-IS_Flow!S5)/(IS_Flow!S3-IS_Flow!S4),"") | Q7: =IFERROR((IS_Flow!T3-IS_Flow!T4-IS_Flow!T5)/(IS_Flow!T3-IS_Flow!T4),"") | R7: =IFERROR((IS_Flow!V3-IS_Flow!V4-IS_Flow!V5)/(IS_Flow!V3-IS_Flow!V4),"") | S7: =IFERROR((IS_Flow!W3-IS_Flow!W4-IS_Flow!W5)/(IS_Flow!W3-IS_Flow!W4),"") | T7: =IFERROR((IS_Flow!X3-IS_Flow!X4-IS_Flow!X5)/(IS_Flow!X3-IS_Flow!X4),"") | U7: =IFERROR((IS_Flow!Y3-IS_Flow!Y4-IS_Flow!Y5)/(IS_Flow!Y3-IS_Flow!Y4),"")
A8: DSO (วัน) | B8: =IFERROR(((BS_Timeline!B3+BS_Timeline!C3)/2)/IS_Flow!B3*90,"") | C8: =IFERROR(((BS_Timeline!C3+BS_Timeline!D3)/2)/IS_Flow!C3*91,"") | D8: =IFERROR(((BS_Timeline!D3+BS_Timeline!E3)/2)/IS_Flow!D3*92,"") | E8: =IFERROR(((BS_Timeline!E3+BS_Timeline!F3)/2)/IS_Flow!E3*92,"") | F8: =IFERROR(((BS_Timeline!F3+BS_Timeline!G3)/2)/IS_Flow!G3*90,"") | G8: =IFERROR(((BS_Timeline!G3+BS_Timeline!H3)/2)/IS_Flow!H3*91,"") | H8: =IFERROR(((BS_Timeline!H3+BS_Timeline!I3)/2)/IS_Flow!I3*92,"") | I8: =IFERROR(((BS_Timeline!I3+BS_Timeline!J3)/2)/IS_Flow!J3*92,"") | J8: =IFERROR(((BS_Timeline!J3+BS_Timeline!K3)/2)/IS_Flow!L3*90,"") | K8: =IFERROR(((BS_Timeline!K3+BS_Timeline!L3)/2)/IS_Flow!M3*91,"") | L8: =IFERROR(((BS_Timeline!L3+BS_Timeline!M3)/2)/IS_Flow!N3*92,"") | M8: =IFERROR(((BS_Timeline!M3+BS_Timeline!N3)/2)/IS_Flow!O3*92,"") | N8: =IFERROR(((BS_Timeline!N3+BS_Timeline!O3)/2)/IS_Flow!Q3*90,"") | O8: =IFERROR(((BS_Timeline!O3+BS_Timeline!P3)/2)/IS_Flow!R3*91,"") | P8: =IFERROR(((BS_Timeline!P3+BS_Timeline!Q3)/2)/IS_Flow!S3*92,"") | Q8: =IFERROR(((BS_Timeline!Q3+BS_Timeline!R3)/2)/IS_Flow!T3*92,"") | R8: =IFERROR(((BS_Timeline!R3+BS_Timeline!S3)/2)/IS_Flow!V3*90,"") | S8: =IFERROR(((BS_Timeline!S3+BS_Timeline!T3)/2)/IS_Flow!W3*91,"") | T8: =IFERROR(((BS_Timeline!T3+BS_Timeline!U3)/2)/IS_Flow!X3*92,"") | U8: =IFERROR(((BS_Timeline!U3+BS_Timeline!V3)/2)/IS_Flow!Y3*92,"")
A9: DIO (วัน) | B9: =IFERROR(((BS_Timeline!B4+BS_Timeline!C4)/2)/IS_Flow!B5*90,"") | C9: =IFERROR(((BS_Timeline!C4+BS_Timeline!D4)/2)/IS_Flow!C5*91,"") | D9: =IFERROR(((BS_Timeline!D4+BS_Timeline!E4)/2)/IS_Flow!D5*92,"") | E9: =IFERROR(((BS_Timeline!E4+BS_Timeline!F4)/2)/IS_Flow!E5*92,"") | F9: =IFERROR(((BS_Timeline!F4+BS_Timeline!G4)/2)/IS_Flow!G5*90,"") | G9: =IFERROR(((BS_Timeline!G4+BS_Timeline!H4)/2)/IS_Flow!H5*91,"") | H9: =IFERROR(((BS_Timeline!H4+BS_Timeline!I4)/2)/IS_Flow!I5*92,"") | I9: =IFERROR(((BS_Timeline!I4+BS_Timeline!J4)/2)/IS_Flow!J5*92,"") | J9: =IFERROR(((BS_Timeline!J4+BS_Timeline!K4)/2)/IS_Flow!L5*90,"") | K9: =IFERROR(((BS_Timeline!K4+BS_Timeline!L4)/2)/IS_Flow!M5*91,"") | L9: =IFERROR(((BS_Timeline!L4+BS_Timeline!M4)/2)/IS_Flow!N5*92,"") | M9: =IFERROR(((BS_Timeline!M4+BS_Timeline!N4)/2)/IS_Flow!O5*92,"") | N9: =IFERROR(((BS_Timeline!N4+BS_Timeline!O4)/2)/IS_Flow!Q5*90,"") | O9: =IFERROR(((BS_Timeline!O4+BS_Timeline!P4)/2)/IS_Flow!R5*91,"") | P9: =IFERROR(((BS_Timeline!P4+BS_Timeline!Q4)/2)/IS_Flow!S5*92,"") | Q9: =IFERROR(((BS_Timeline!Q4+BS_Timeline!R4)/2)/IS_Flow!T5*92,"") | R9: =IFERROR(((BS_Timeline!R4+BS_Timeline!S4)/2)/IS_Flow!V5*90,"") | S9: =IFERROR(((BS_Timeline!S4+BS_Timeline!T4)/2)/IS_Flow!W5*91,"") | T9: =IFERROR(((BS_Timeline!T4+BS_Timeline!U4)/2)/IS_Flow!X5*92,"") | U9: =IFERROR(((BS_Timeline!U4+BS_Timeline!V4)/2)/IS_Flow!Y5*92,"")
A10: DPO (วัน) | B10: =IFERROR(((BS_Timeline!B5+BS_Timeline!C5)/2)/IS_Flow!B5*90,"") | C10: =IFERROR(((BS_Timeline!C5+BS_Timeline!D5)/2)/IS_Flow!C5*91,"") | D10: =IFERROR(((BS_Timeline!D5+BS_Timeline!E5)/2)/IS_Flow!D5*92,"") | E10: =IFERROR(((BS_Timeline!E5+BS_Timeline!F5)/2)/IS_Flow!E5*92,"") | F10: =IFERROR(((BS_Timeline!F5+BS_Timeline!G5)/2)/IS_Flow!G5*90,"") | G10: =IFERROR(((BS_Timeline!G5+BS_Timeline!H5)/2)/IS_Flow!H5*91,"") | H10: =IFERROR(((BS_Timeline!H5+BS_Timeline!I5)/2)/IS_Flow!I5*92,"") | I10: =IFERROR(((BS_Timeline!I5+BS_Timeline!J5)/2)/IS_Flow!J5*92,"") | J10: =IFERROR(((BS_Timeline!J5+BS_Timeline!K5)/2)/IS_Flow!L5*90,"") | K10: =IFERROR(((BS_Timeline!K5+BS_Timeline!L5)/2)/IS_Flow!M5*91,"") | L10: =IFERROR(((BS_Timeline!L5+BS_Timeline!M5)/2)/IS_Flow!N5*92,"") | M10: =IFERROR(((BS_Timeline!M5+BS_Timeline!N5)/2)/IS_Flow!O5*92,"") | N10: =IFERROR(((BS_Timeline!N5+BS_Timeline!O5)/2)/IS_Flow!Q5*90,"") | O10: =IFERROR(((BS_Timeline!O5+BS_Timeline!P5)/2)/IS_Flow!R5*91,"") | P10: =IFERROR(((BS_Timeline!P5+BS_Timeline!Q5)/2)/IS_Flow!S5*92,"") | Q10: =IFERROR(((BS_Timeline!Q5+BS_Timeline!R5)/2)/IS_Flow!T5*92,"") | R10: =IFERROR(((BS_Timeline!R5+BS_Timeline!S5)/2)/IS_Flow!V5*90,"") | S10: =IFERROR(((BS_Timeline!S5+BS_Timeline!T5)/2)/IS_Flow!W5*91,"") | T10: =IFERROR(((BS_Timeline!T5+BS_Timeline!U5)/2)/IS_Flow!X5*92,"") | U10: =IFERROR(((BS_Timeline!U5+BS_Timeline!V5)/2)/IS_Flow!Y5*92,"")
A11: CCC (วัน) | B11: =IFERROR(B8+B9-B10,"") | C11: =IFERROR(C8+C9-C10,"") | D11: =IFERROR(D8+D9-D10,"") | E11: =IFERROR(E8+E9-E10,"") | F11: =IFERROR(F8+F9-F10,"") | G11: =IFERROR(G8+G9-G10,"") | H11: =IFERROR(H8+H9-H10,"") | I11: =IFERROR(I8+I9-I10,"") | ... U11: =IFERROR(U8+U9-U10,"")
A12: ROA รายไตรมาส (%) | B12: =IFERROR(IS_Flow!B6/((BS_Timeline!B6+BS_Timeline!C6)/2),"") | C12: =IFERROR(IS_Flow!C6/((BS_Timeline!C6+BS_Timeline!D6)/2),"") | D12: =IFERROR(IS_Flow!D6/((BS_Timeline!D6+BS_Timeline!E6)/2),"") | E12: =IFERROR(IS_Flow!E6/((BS_Timeline!E6+BS_Timeline!F6)/2),"") | F12: =IFERROR(IS_Flow!G6/((BS_Timeline!F6+BS_Timeline!G6)/2),"") | G12: =IFERROR(IS_Flow!H6/((BS_Timeline!G6+BS_Timeline!H6)/2),"") | H12: =IFERROR(IS_Flow!I6/((BS_Timeline!H6+BS_Timeline!I6)/2),"") | I12: =IFERROR(IS_Flow!J6/((BS_Timeline!I6+BS_Timeline!J6)/2),"") | J12: =IFERROR(IS_Flow!L6/((BS_Timeline!J6+BS_Timeline!K6)/2),"") | K12: =IFERROR(IS_Flow!M6/((BS_Timeline!K6+BS_Timeline!L6)/2),"") | L12: =IFERROR(IS_Flow!N6/((BS_Timeline!L6+BS_Timeline!M6)/2),"") | M12: =IFERROR(IS_Flow!O6/((BS_Timeline!M6+BS_Timeline!N6)/2),"") | N12: =IFERROR(IS_Flow!Q6/((BS_Timeline!N6+BS_Timeline!O6)/2),"") | O12: =IFERROR(IS_Flow!R6/((BS_Timeline!O6+BS_Timeline!P6)/2),"") | P12: =IFERROR(IS_Flow!S6/((BS_Timeline!P6+BS_Timeline!Q6)/2),"") | Q12: =IFERROR(IS_Flow!T6/((BS_Timeline!Q6+BS_Timeline!R6)/2),"") | R12: =IFERROR(IS_Flow!V6/((BS_Timeline!R6+BS_Timeline!S6)/2),"") | S12: =IFERROR(IS_Flow!W6/((BS_Timeline!S6+BS_Timeline!T6)/2),"") | T12: =IFERROR(IS_Flow!X6/((BS_Timeline!T6+BS_Timeline!U6)/2),"") | U12: =IFERROR(IS_Flow!Y6/((BS_Timeline!U6+BS_Timeline!V6)/2),"")
A13: ROE รายไตรมาส (%) | B13: =IFERROR(IS_Flow!B6/((BS_Timeline!B7+BS_Timeline!C7)/2),"") | C13: =IFERROR(IS_Flow!C6/((BS_Timeline!C7+BS_Timeline!D7)/2),"") | D13: =IFERROR(IS_Flow!D6/((BS_Timeline!D7+BS_Timeline!E7)/2),"") | E13: =IFERROR(IS_Flow!E6/((BS_Timeline!E7+BS_Timeline!F7)/2),"") | F13: =IFERROR(IS_Flow!G6/((BS_Timeline!F7+BS_Timeline!G7)/2),"") | G13: =IFERROR(IS_Flow!H6/((BS_Timeline!G7+BS_Timeline!H7)/2),"") | H13: =IFERROR(IS_Flow!I6/((BS_Timeline!H7+BS_Timeline!I7)/2),"") | I13: =IFERROR(IS_Flow!J6/((BS_Timeline!I7+BS_Timeline!J7)/2),"") | J13: =IFERROR(IS_Flow!L6/((BS_Timeline!J7+BS_Timeline!K7)/2),"") | K13: =IFERROR(IS_Flow!M6/((BS_Timeline!K7+BS_Timeline!L7)/2),"") | L13: =IFERROR(IS_Flow!N6/((BS_Timeline!L7+BS_Timeline!M7)/2),"") | M13: =IFERROR(IS_Flow!O6/((BS_Timeline!M7+BS_Timeline!N7)/2),"") | N13: =IFERROR(IS_Flow!Q6/((BS_Timeline!N7+BS_Timeline!O7)/2),"") | O13: =IFERROR(IS_Flow!R6/((BS_Timeline!O7+BS_Timeline!P7)/2),"") | P13: =IFERROR(IS_Flow!S6/((BS_Timeline!P7+BS_Timeline!Q7)/2),"") | Q13: =IFERROR(IS_Flow!T6/((BS_Timeline!Q7+BS_Timeline!R7)/2),"") | R13: =IFERROR(IS_Flow!V6/((BS_Timeline!R7+BS_Timeline!S7)/2),"") | S13: =IFERROR(IS_Flow!W6/((BS_Timeline!S7+BS_Timeline!T7)/2),"") | T13: =IFERROR(IS_Flow!X6/((BS_Timeline!T7+BS_Timeline!U7)/2),"") | U13: =IFERROR(IS_Flow!Y6/((BS_Timeline!U7+BS_Timeline!V7)/2),"")
A14: D/E (เท่า) | B14: =IFERROR(BS_Timeline!C8/BS_Timeline!C7,"") | C14: =IFERROR(BS_Timeline!D8/BS_Timeline!D7,"") | D14: =IFERROR(BS_Timeline!E8/BS_Timeline!E7,"") | E14: =IFERROR(BS_Timeline!F8/BS_Timeline!F7,"") | F14: =IFERROR(BS_Timeline!G8/BS_Timeline!G7,"") | G14: =IFERROR(BS_Timeline!H8/BS_Timeline!H7,"") | H14: =IFERROR(BS_Timeline!I8/BS_Timeline!I7,"") | I14: =IFERROR(BS_Timeline!J8/BS_Timeline!J7,"") | ... U14: =IFERROR(BS_Timeline!V8/BS_Timeline!V7,"")
A15: ■ CENTEL
A16: รายได้รวม (ล้านบาท) | B16: =IS_Flow!B9 | C16: =IS_Flow!C9 | D16: =IS_Flow!D9 | E16: =IS_Flow!E9 | F16: =IS_Flow!G9 | G16: =IS_Flow!H9 | H16: =IS_Flow!I9 | I16: =IS_Flow!J9 | J16: =IS_Flow!L9 | K16: =IS_Flow!M9 | L16: =IS_Flow!N9 | M16: =IS_Flow!O9 | N16: =IS_Flow!Q9 | O16: =IS_Flow!R9 | P16: =IS_Flow!S9 | Q16: =IS_Flow!T9 | R16: =IS_Flow!V9 | S16: =IS_Flow!W9 | T16: =IS_Flow!X9 | U16: =IS_Flow!Y9
A17: ต้นทุนขาย (ล้านบาท) | B17: =IS_Flow!B11 | C17: =IS_Flow!C11 | D17: =IS_Flow!D11 | E17: =IS_Flow!E11 | F17: =IS_Flow!G11 | G17: =IS_Flow!H11 | H17: =IS_Flow!I11 | I17: =IS_Flow!J11 | J17: =IS_Flow!L11 | K17: =IS_Flow!M11 | L17: =IS_Flow!N11 | M17: =IS_Flow!O11 | N17: =IS_Flow!Q11 | O17: =IS_Flow!R11 | P17: =IS_Flow!S11 | Q17: =IS_Flow!T11 | R17: =IS_Flow!V11 | S17: =IS_Flow!W11 | T17: =IS_Flow!X11 | U17: =IS_Flow!Y11
A18: กำไรสุทธิ (ล้านบาท) | B18: =IS_Flow!B12 | C18: =IS_Flow!C12 | D18: =IS_Flow!D12 | E18: =IS_Flow!E12 | F18: =IS_Flow!G12 | G18: =IS_Flow!H12 | H18: =IS_Flow!I12 | I18: =IS_Flow!J12 | J18: =IS_Flow!L12 | K18: =IS_Flow!M12 | L18: =IS_Flow!N12 | M18: =IS_Flow!O12 | N18: =IS_Flow!Q12 | O18: =IS_Flow!R12 | P18: =IS_Flow!S12 | Q18: =IS_Flow!T12 | R18: =IS_Flow!V12 | S18: =IS_Flow!W12 | T18: =IS_Flow!X12 | U18: =IS_Flow!Y12
A19: NPM (%) | B19: =IFERROR(IS_Flow!B12/IS_Flow!B9,"") | C19: =IFERROR(IS_Flow!C12/IS_Flow!C9,"") | D19: =IFERROR(IS_Flow!D12/IS_Flow!D9,"") | E19: =IFERROR(IS_Flow!E12/IS_Flow!E9,"") | F19: =IFERROR(IS_Flow!G12/IS_Flow!G9,"") | G19: =IFERROR(IS_Flow!H12/IS_Flow!H9,"") | H19: =IFERROR(IS_Flow!I12/IS_Flow!I9,"") | I19: =IFERROR(IS_Flow!J12/IS_Flow!J9,"") | J19: =IFERROR(IS_Flow!L12/IS_Flow!L9,"") | K19: =IFERROR(IS_Flow!M12/IS_Flow!M9,"") | L19: =IFERROR(IS_Flow!N12/IS_Flow!N9,"") | M19: =IFERROR(IS_Flow!O12/IS_Flow!O9,"") | N19: =IFERROR(IS_Flow!Q12/IS_Flow!Q9,"") | O19: =IFERROR(IS_Flow!R12/IS_Flow!R9,"") | P19: =IFERROR(IS_Flow!S12/IS_Flow!S9,"") | Q19: =IFERROR(IS_Flow!T12/IS_Flow!T9,"") | R19: =IFERROR(IS_Flow!V12/IS_Flow!V9,"") | S19: =IFERROR(IS_Flow!W12/IS_Flow!W9,"") | T19: =IFERROR(IS_Flow!X12/IS_Flow!X9,"") | U19: =IFERROR(IS_Flow!Y12/IS_Flow!Y9,"")
A20: Gross Margin (%) | B20: =IFERROR((IS_Flow!B9-IS_Flow!B10-IS_Flow!B11)/(IS_Flow!B9-IS_Flow!B10),"") | C20: =IFERROR((IS_Flow!C9-IS_Flow!C10-IS_Flow!C11)/(IS_Flow!C9-IS_Flow!C10),"") | D20: =IFERROR((IS_Flow!D9-IS_Flow!D10-IS_Flow!D11)/(IS_Flow!D9-IS_Flow!D10),"") | E20: =IFERROR((IS_Flow!E9-IS_Flow!E10-IS_Flow!E11)/(IS_Flow!E9-IS_Flow!E10),"") | F20: =IFERROR((IS_Flow!G9-IS_Flow!G10-IS_Flow!G11)/(IS_Flow!G9-IS_Flow!G10),"") | G20: =IFERROR((IS_Flow!H9-IS_Flow!H10-IS_Flow!H11)/(IS_Flow!H9-IS_Flow!H10),"") | H20: =IFERROR((IS_Flow!I9-IS_Flow!I10-IS_Flow!I11)/(IS_Flow!I9-IS_Flow!I10),"") | I20: =IFERROR((IS_Flow!J9-IS_Flow!J10-IS_Flow!J11)/(IS_Flow!J9-IS_Flow!J10),"") | J20: =IFERROR((IS_Flow!L9-IS_Flow!L10-IS_Flow!L11)/(IS_Flow!L9-IS_Flow!L10),"") | K20: =IFERROR((IS_Flow!M9-IS_Flow!M10-IS_Flow!M11)/(IS_Flow!M9-IS_Flow!M10),"") | L20: =IFERROR((IS_Flow!N9-IS_Flow!N10-IS_Flow!N11)/(IS_Flow!N9-IS_Flow!N10),"") | M20: =IFERROR((IS_Flow!O9-IS_Flow!O10-IS_Flow!O11)/(IS_Flow!O9-IS_Flow!O10),"") | N20: =IFERROR((IS_Flow!Q9-IS_Flow!Q10-IS_Flow!Q11)/(IS_Flow!Q9-IS_Flow!Q10),"") | O20: =IFERROR((IS_Flow!R9-IS_Flow!R10-IS_Flow!R11)/(IS_Flow!R9-IS_Flow!R10),"") | P20: =IFERROR((IS_Flow!S9-IS_Flow!S10-IS_Flow!S11)/(IS_Flow!S9-IS_Flow!S10),"") | Q20: =IFERROR((IS_Flow!T9-IS_Flow!T10-IS_Flow!T11)/(IS_Flow!T9-IS_Flow!T10),"") | R20: =IFERROR((IS_Flow!V9-IS_Flow!V10-IS_Flow!V11)/(IS_Flow!V9-IS_Flow!V10),"") | S20: =IFERROR((IS_Flow!W9-IS_Flow!W10-IS_Flow!W11)/(IS_Flow!W9-IS_Flow!W10),"") | T20: =IFERROR((IS_Flow!X9-IS_Flow!X10-IS_Flow!X11)/(IS_Flow!X9-IS_Flow!X10),"") | U20: =IFERROR((IS_Flow!Y9-IS_Flow!Y10-IS_Flow!Y11)/(IS_Flow!Y9-IS_Flow!Y10),"")
A21: DSO (วัน) | B21: =IFERROR(((BS_Timeline!B10+BS_Timeline!C10)/2)/IS_Flow!B9*90,"") | C21: =IFERROR(((BS_Timeline!C10+BS_Timeline!D10)/2)/IS_Flow!C9*91,"") | D21: =IFERROR(((BS_Timeline!D10+BS_Timeline!E10)/2)/IS_Flow!D9*92,"") | E21: =IFERROR(((BS_Timeline!E10+BS_Timeline!F10)/2)/IS_Flow!E9*92,"") | F21: =IFERROR(((BS_Timeline!F10+BS_Timeline!G10)/2)/IS_Flow!G9*90,"") | G21: =IFERROR(((BS_Timeline!G10+BS_Timeline!H10)/2)/IS_Flow!H9*91,"") | H21: =IFERROR(((BS_Timeline!H10+BS_Timeline!I10)/2)/IS_Flow!I9*92,"") | I21: =IFERROR(((BS_Timeline!I10+BS_Timeline!J10)/2)/IS_Flow!J9*92,"") | J21: =IFERROR(((BS_Timeline!J10+BS_Timeline!K10)/2)/IS_Flow!L9*90,"") | K21: =IFERROR(((BS_Timeline!K10+BS_Timeline!L10)/2)/IS_Flow!M9*91,"") | L21: =IFERROR(((BS_Timeline!L10+BS_Timeline!M10)/2)/IS_Flow!N9*92,"") | M21: =IFERROR(((BS_Timeline!M10+BS_Timeline!N10)/2)/IS_Flow!O9*92,"") | N21: =IFERROR(((BS_Timeline!N10+BS_Timeline!O10)/2)/IS_Flow!Q9*90,"") | O21: =IFERROR(((BS_Timeline!O10+BS_Timeline!P10)/2)/IS_Flow!R9*91,"") | P21: =IFERROR(((BS_Timeline!P10+BS_Timeline!Q10)/2)/IS_Flow!S9*92,"") | Q21: =IFERROR(((BS_Timeline!Q10+BS_Timeline!R10)/2)/IS_Flow!T9*92,"") | R21: =IFERROR(((BS_Timeline!R10+BS_Timeline!S10)/2)/IS_Flow!V9*90,"") | S21: =IFERROR(((BS_Timeline!S10+BS_Timeline!T10)/2)/IS_Flow!W9*91,"") | T21: =IFERROR(((BS_Timeline!T10+BS_Timeline!U10)/2)/IS_Flow!X9*92,"") | U21: =IFERROR(((BS_Timeline!U10+BS_Timeline!V10)/2)/IS_Flow!Y9*92,"")
A22: DIO (วัน) | B22: =IFERROR(((BS_Timeline!B11+BS_Timeline!C11)/2)/IS_Flow!B11*90,"") | C22: =IFERROR(((BS_Timeline!C11+BS_Timeline!D11)/2)/IS_Flow!C11*91,"") | D22: =IFERROR(((BS_Timeline!D11+BS_Timeline!E11)/2)/IS_Flow!D11*92,"") | E22: =IFERROR(((BS_Timeline!E11+BS_Timeline!F11)/2)/IS_Flow!E11*92,"") | F22: =IFERROR(((BS_Timeline!F11+BS_Timeline!G11)/2)/IS_Flow!G11*90,"") | G22: =IFERROR(((BS_Timeline!G11+BS_Timeline!H11)/2)/IS_Flow!H11*91,"") | H22: =IFERROR(((BS_Timeline!H11+BS_Timeline!I11)/2)/IS_Flow!I11*92,"") | I22: =IFERROR(((BS_Timeline!I11+BS_Timeline!J11)/2)/IS_Flow!J11*92,"") | J22: =IFERROR(((BS_Timeline!J11+BS_Timeline!K11)/2)/IS_Flow!L11*90,"") | K22: =IFERROR(((BS_Timeline!K11+BS_Timeline!L11)/2)/IS_Flow!M11*91,"") | L22: =IFERROR(((BS_Timeline!L11+BS_Timeline!M11)/2)/IS_Flow!N11*92,"") | M22: =IFERROR(((BS_Timeline!M11+BS_Timeline!N11)/2)/IS_Flow!O11*92,"") | N22: =IFERROR(((BS_Timeline!N11+BS_Timeline!O11)/2)/IS_Flow!Q11*90,"") | O22: =IFERROR(((BS_Timeline!O11+BS_Timeline!P11)/2)/IS_Flow!R11*91,"") | P22: =IFERROR(((BS_Timeline!P11+BS_Timeline!Q11)/2)/IS_Flow!S11*92,"") | Q22: =IFERROR(((BS_Timeline!Q11+BS_Timeline!R11)/2)/IS_Flow!T11*92,"") | R22: =IFERROR(((BS_Timeline!R11+BS_Timeline!S11)/2)/IS_Flow!V11*90,"") | S22: =IFERROR(((BS_Timeline!S11+BS_Timeline!T11)/2)/IS_Flow!W11*91,"") | T22: =IFERROR(((BS_Timeline!T11+BS_Timeline!U11)/2)/IS_Flow!X11*92,"") | U22: =IFERROR(((BS_Timeline!U11+BS_Timeline!V11)/2)/IS_Flow!Y11*92,"")
A23: DPO (วัน) | B23: =IFERROR(((BS_Timeline!B12+BS_Timeline!C12)/2)/IS_Flow!B11*90,"") | C23: =IFERROR(((BS_Timeline!C12+BS_Timeline!D12)/2)/IS_Flow!C11*91,"") | D23: =IFERROR(((BS_Timeline!D12+BS_Timeline!E12)/2)/IS_Flow!D11*92,"") | E23: =IFERROR(((BS_Timeline!E12+BS_Timeline!F12)/2)/IS_Flow!E11*92,"") | F23: =IFERROR(((BS_Timeline!F12+BS_Timeline!G12)/2)/IS_Flow!G11*90,"") | G23: =IFERROR(((BS_Timeline!G12+BS_Timeline!H12)/2)/IS_Flow!H11*91,"") | H23: =IFERROR(((BS_Timeline!H12+BS_Timeline!I12)/2)/IS_Flow!I11*92,"") | I23: =IFERROR(((BS_Timeline!I12+BS_Timeline!J12)/2)/IS_Flow!J11*92,"") | J23: =IFERROR(((BS_Timeline!J12+BS_Timeline!K12)/2)/IS_Flow!L11*90,"") | K23: =IFERROR(((BS_Timeline!K12+BS_Timeline!L12)/2)/IS_Flow!M11*91,"") | L23: =IFERROR(((BS_Timeline!L12+BS_Timeline!M12)/2)/IS_Flow!N11*92,"") | M23: =IFERROR(((BS_Timeline!M12+BS_Timeline!N12)/2)/IS_Flow!O11*92,"") | N23: =IFERROR(((BS_Timeline!N12+BS_Timeline!O12)/2)/IS_Flow!Q11*90,"") | O23: =IFERROR(((BS_Timeline!O12+BS_Timeline!P12)/2)/IS_Flow!R11*91,"") | P23: =IFERROR(((BS_Timeline!P12+BS_Timeline!Q12)/2)/IS_Flow!S11*92,"") | Q23: =IFERROR(((BS_Timeline!Q12+BS_Timeline!R12)/2)/IS_Flow!T11*92,"") | R23: =IFERROR(((BS_Timeline!R12+BS_Timeline!S12)/2)/IS_Flow!V11*90,"") | S23: =IFERROR(((BS_Timeline!S12+BS_Timeline!T12)/2)/IS_Flow!W11*91,"") | T23: =IFERROR(((BS_Timeline!T12+BS_Timeline!U12)/2)/IS_Flow!X11*92,"") | U23: =IFERROR(((BS_Timeline!U12+BS_Timeline!V12)/2)/IS_Flow!Y11*92,"")
A24: CCC (วัน) | B24: =IFERROR(B21+B22-B23,"") | C24: =IFERROR(C21+C22-C23,"") | D24: =IFERROR(D21+D22-D23,"") | E24: =IFERROR(E21+E22-E23,"") | F24: =IFERROR(F21+F22-F23,"") | G24: =IFERROR(G21+G22-G23,"") | H24: =IFERROR(H21+H22-H23,"") | I24: =IFERROR(I21+I22-I23,"") | ... U24: =IFERROR(U21+U22-U23,"")
A25: ROA รายไตรมาส (%) | B25: =IFERROR(IS_Flow!B12/((BS_Timeline!B13+BS_Timeline!C13)/2),"") | C25: =IFERROR(IS_Flow!C12/((BS_Timeline!C13+BS_Timeline!D13)/2),"") | D25: =IFERROR(IS_Flow!D12/((BS_Timeline!D13+BS_Timeline!E13)/2),"") | E25: =IFERROR(IS_Flow!E12/((BS_Timeline!E13+BS_Timeline!F13)/2),"") | F25: =IFERROR(IS_Flow!G12/((BS_Timeline!F13+BS_Timeline!G13)/2),"") | G25: =IFERROR(IS_Flow!H12/((BS_Timeline!G13+BS_Timeline!H13)/2),"") | H25: =IFERROR(IS_Flow!I12/((BS_Timeline!H13+BS_Timeline!I13)/2),"") | I25: =IFERROR(IS_Flow!J12/((BS_Timeline!I13+BS_Timeline!J13)/2),"") | J25: =IFERROR(IS_Flow!L12/((BS_Timeline!J13+BS_Timeline!K13)/2),"") | K25: =IFERROR(IS_Flow!M12/((BS_Timeline!K13+BS_Timeline!L13)/2),"") | L25: =IFERROR(IS_Flow!N12/((BS_Timeline!L13+BS_Timeline!M13)/2),"") | M25: =IFERROR(IS_Flow!O12/((BS_Timeline!M13+BS_Timeline!N13)/2),"") | N25: =IFERROR(IS_Flow!Q12/((BS_Timeline!N13+BS_Timeline!O13)/2),"") | O25: =IFERROR(IS_Flow!R12/((BS_Timeline!O13+BS_Timeline!P13)/2),"") | P25: =IFERROR(IS_Flow!S12/((BS_Timeline!P13+BS_Timeline!Q13)/2),"") | Q25: =IFERROR(IS_Flow!T12/((BS_Timeline!Q13+BS_Timeline!R13)/2),"") | R25: =IFERROR(IS_Flow!V12/((BS_Timeline!R13+BS_Timeline!S13)/2),"") | S25: =IFERROR(IS_Flow!W12/((BS_Timeline!S13+BS_Timeline!T13)/2),"") | T25: =IFERROR(IS_Flow!X12/((BS_Timeline!T13+BS_Timeline!U13)/2),"") | U25: =IFERROR(IS_Flow!Y12/((BS_Timeline!U13+BS_Timeline!V13)/2),"")
A26: ROE รายไตรมาส (%) | B26: =IFERROR(IS_Flow!B12/((BS_Timeline!B14+BS_Timeline!C14)/2),"") | C26: =IFERROR(IS_Flow!C12/((BS_Timeline!C14+BS_Timeline!D14)/2),"") | D26: =IFERROR(IS_Flow!D12/((BS_Timeline!D14+BS_Timeline!E14)/2),"") | E26: =IFERROR(IS_Flow!E12/((BS_Timeline!E14+BS_Timeline!F14)/2),"") | F26: =IFERROR(IS_Flow!G12/((BS_Timeline!F14+BS_Timeline!G14)/2),"") | G26: =IFERROR(IS_Flow!H12/((BS_Timeline!G14+BS_Timeline!H14)/2),"") | H26: =IFERROR(IS_Flow!I12/((BS_Timeline!H14+BS_Timeline!I14)/2),"") | I26: =IFERROR(IS_Flow!J12/((BS_Timeline!I14+BS_Timeline!J14)/2),"") | J26: =IFERROR(IS_Flow!L12/((BS_Timeline!J14+BS_Timeline!K14)/2),"") | K26: =IFERROR(IS_Flow!M12/((BS_Timeline!K14+BS_Timeline!L14)/2),"") | L26: =IFERROR(IS_Flow!N12/((BS_Timeline!L14+BS_Timeline!M14)/2),"") | M26: =IFERROR(IS_Flow!O12/((BS_Timeline!M14+BS_Timeline!N14)/2),"") | N26: =IFERROR(IS_Flow!Q12/((BS_Timeline!N14+BS_Timeline!O14)/2),"") | O26: =IFERROR(IS_Flow!R12/((BS_Timeline!O14+BS_Timeline!P14)/2),"") | P26: =IFERROR(IS_Flow!S12/((BS_Timeline!P14+BS_Timeline!Q14)/2),"") | Q26: =IFERROR(IS_Flow!T12/((BS_Timeline!Q14+BS_Timeline!R14)/2),"") | R26: =IFERROR(IS_Flow!V12/((BS_Timeline!R14+BS_Timeline!S14)/2),"") | S26: =IFERROR(IS_Flow!W12/((BS_Timeline!S14+BS_Timeline!T14)/2),"") | T26: =IFERROR(IS_Flow!X12/((BS_Timeline!T14+BS_Timeline!U14)/2),"") | U26: =IFERROR(IS_Flow!Y12/((BS_Timeline!U14+BS_Timeline!V14)/2),"")
A27: D/E (เท่า) | B27: =IFERROR(BS_Timeline!C15/BS_Timeline!C14,"") | C27: =IFERROR(BS_Timeline!D15/BS_Timeline!D14,"") | D27: =IFERROR(BS_Timeline!E15/BS_Timeline!E14,"") | E27: =IFERROR(BS_Timeline!F15/BS_Timeline!F14,"") | F27: =IFERROR(BS_Timeline!G15/BS_Timeline!G14,"") | G27: =IFERROR(BS_Timeline!H15/BS_Timeline!H14,"") | H27: =IFERROR(BS_Timeline!I15/BS_Timeline!I14,"") | I27: =IFERROR(BS_Timeline!J15/BS_Timeline!J14,"") | ... U27: =IFERROR(BS_Timeline!V15/BS_Timeline!V14,"")
A28: ■ DUSIT
A29: รายได้รวม (ล้านบาท) | B29: =IS_Flow!B15 | C29: =IS_Flow!C15 | D29: =IS_Flow!D15 | E29: =IS_Flow!E15 | F29: =IS_Flow!G15 | G29: =IS_Flow!H15 | H29: =IS_Flow!I15 | I29: =IS_Flow!J15 | J29: =IS_Flow!L15 | K29: =IS_Flow!M15 | L29: =IS_Flow!N15 | M29: =IS_Flow!O15 | N29: =IS_Flow!Q15 | O29: =IS_Flow!R15 | P29: =IS_Flow!S15 | Q29: =IS_Flow!T15 | R29: =IS_Flow!V15 | S29: =IS_Flow!W15 | T29: =IS_Flow!X15 | U29: =IS_Flow!Y15
A30: ต้นทุนขาย (ล้านบาท) | B30: =IS_Flow!B17 | C30: =IS_Flow!C17 | D30: =IS_Flow!D17 | E30: =IS_Flow!E17 | F30: =IS_Flow!G17 | G30: =IS_Flow!H17 | H30: =IS_Flow!I17 | I30: =IS_Flow!J17 | J30: =IS_Flow!L17 | K30: =IS_Flow!M17 | L30: =IS_Flow!N17 | M30: =IS_Flow!O17 | N30: =IS_Flow!Q17 | O30: =IS_Flow!R17 | P30: =IS_Flow!S17 | Q30: =IS_Flow!T17 | R30: =IS_Flow!V17 | S30: =IS_Flow!W17 | T30: =IS_Flow!X17 | U30: =IS_Flow!Y17
A31: กำไรสุทธิ (ล้านบาท) | B31: =IS_Flow!B18 | C31: =IS_Flow!C18 | D31: =IS_Flow!D18 | E31: =IS_Flow!E18 | F31: =IS_Flow!G18 | G31: =IS_Flow!H18 | H31: =IS_Flow!I18 | I31: =IS_Flow!J18 | J31: =IS_Flow!L18 | K31: =IS_Flow!M18 | L31: =IS_Flow!N18 | M31: =IS_Flow!O18 | N31: =IS_Flow!Q18 | O31: =IS_Flow!R18 | P31: =IS_Flow!S18 | Q31: =IS_Flow!T18 | R31: =IS_Flow!V18 | S31: =IS_Flow!W18 | T31: =IS_Flow!X18 | U31: =IS_Flow!Y18
A32: NPM (%) | B32: =IFERROR(IS_Flow!B18/IS_Flow!B15,"") | C32: =IFERROR(IS_Flow!C18/IS_Flow!C15,"") | D32: =IFERROR(IS_Flow!D18/IS_Flow!D15,"") | E32: =IFERROR(IS_Flow!E18/IS_Flow!E15,"") | F32: =IFERROR(IS_Flow!G18/IS_Flow!G15,"") | G32: =IFERROR(IS_Flow!H18/IS_Flow!H15,"") | H32: =IFERROR(IS_Flow!I18/IS_Flow!I15,"") | I32: =IFERROR(IS_Flow!J18/IS_Flow!J15,"") | J32: =IFERROR(IS_Flow!L18/IS_Flow!L15,"") | K32: =IFERROR(IS_Flow!M18/IS_Flow!M15,"") | L32: =IFERROR(IS_Flow!N18/IS_Flow!N15,"") | M32: =IFERROR(IS_Flow!O18/IS_Flow!O15,"") | N32: =IFERROR(IS_Flow!Q18/IS_Flow!Q15,"") | O32: =IFERROR(IS_Flow!R18/IS_Flow!R15,"") | P32: =IFERROR(IS_Flow!S18/IS_Flow!S15,"") | Q32: =IFERROR(IS_Flow!T18/IS_Flow!T15,"") | R32: =IFERROR(IS_Flow!V18/IS_Flow!V15,"") | S32: =IFERROR(IS_Flow!W18/IS_Flow!W15,"") | T32: =IFERROR(IS_Flow!X18/IS_Flow!X15,"") | U32: =IFERROR(IS_Flow!Y18/IS_Flow!Y15,"")
A33: Gross Margin (%) | B33: =IFERROR((IS_Flow!B15-IS_Flow!B16-IS_Flow!B17)/(IS_Flow!B15-IS_Flow!B16),"") | C33: =IFERROR((IS_Flow!C15-IS_Flow!C16-IS_Flow!C17)/(IS_Flow!C15-IS_Flow!C16),"") | D33: =IFERROR((IS_Flow!D15-IS_Flow!D16-IS_Flow!D17)/(IS_Flow!D15-IS_Flow!D16),"") | E33: =IFERROR((IS_Flow!E15-IS_Flow!E16-IS_Flow!E17)/(IS_Flow!E15-IS_Flow!E16),"") | F33: =IFERROR((IS_Flow!G15-IS_Flow!G16-IS_Flow!G17)/(IS_Flow!G15-IS_Flow!G16),"") | G33: =IFERROR((IS_Flow!H15-IS_Flow!H16-IS_Flow!H17)/(IS_Flow!H15-IS_Flow!H16),"") | H33: =IFERROR((IS_Flow!I15-IS_Flow!I16-IS_Flow!I17)/(IS_Flow!I15-IS_Flow!I16),"") | I33: =IFERROR((IS_Flow!J15-IS_Flow!J16-IS_Flow!J17)/(IS_Flow!J15-IS_Flow!J16),"") | J33: =IFERROR((IS_Flow!L15-IS_Flow!L16-IS_Flow!L17)/(IS_Flow!L15-IS_Flow!L16),"") | K33: =IFERROR((IS_Flow!M15-IS_Flow!M16-IS_Flow!M17)/(IS_Flow!M15-IS_Flow!M16),"") | L33: =IFERROR((IS_Flow!N15-IS_Flow!N16-IS_Flow!N17)/(IS_Flow!N15-IS_Flow!N16),"") | M33: =IFERROR((IS_Flow!O15-IS_Flow!O16-IS_Flow!O17)/(IS_Flow!O15-IS_Flow!O16),"") | N33: =IFERROR((IS_Flow!Q15-IS_Flow!Q16-IS_Flow!Q17)/(IS_Flow!Q15-IS_Flow!Q16),"") | O33: =IFERROR((IS_Flow!R15-IS_Flow!R16-IS_Flow!R17)/(IS_Flow!R15-IS_Flow!R16),"") | P33: =IFERROR((IS_Flow!S15-IS_Flow!S16-IS_Flow!S17)/(IS_Flow!S15-IS_Flow!S16),"") | Q33: =IFERROR((IS_Flow!T15-IS_Flow!T16-IS_Flow!T17)/(IS_Flow!T15-IS_Flow!T16),"") | R33: =IFERROR((IS_Flow!V15-IS_Flow!V16-IS_Flow!V17)/(IS_Flow!V15-IS_Flow!V16),"") | S33: =IFERROR((IS_Flow!W15-IS_Flow!W16-IS_Flow!W17)/(IS_Flow!W15-IS_Flow!W16),"") | T33: =IFERROR((IS_Flow!X15-IS_Flow!X16-IS_Flow!X17)/(IS_Flow!X15-IS_Flow!X16),"") | U33: =IFERROR((IS_Flow!Y15-IS_Flow!Y16-IS_Flow!Y17)/(IS_Flow!Y15-IS_Flow!Y16),"")
A34: DSO (วัน) | B34: =IFERROR(((BS_Timeline!B17+BS_Timeline!C17)/2)/IS_Flow!B15*90,"") | C34: =IFERROR(((BS_Timeline!C17+BS_Timeline!D17)/2)/IS_Flow!C15*91,"") | D34: =IFERROR(((BS_Timeline!D17+BS_Timeline!E17)/2)/IS_Flow!D15*92,"") | E34: =IFERROR(((BS_Timeline!E17+BS_Timeline!F17)/2)/IS_Flow!E15*92,"") | F34: =IFERROR(((BS_Timeline!F17+BS_Timeline!G17)/2)/IS_Flow!G15*90,"") | G34: =IFERROR(((BS_Timeline!G17+BS_Timeline!H17)/2)/IS_Flow!H15*91,"") | H34: =IFERROR(((BS_Timeline!H17+BS_Timeline!I17)/2)/IS_Flow!I15*92,"") | I34: =IFERROR(((BS_Timeline!I17+BS_Timeline!J17)/2)/IS_Flow!J15*92,"") | J34: =IFERROR(((BS_Timeline!J17+BS_Timeline!K17)/2)/IS_Flow!L15*90,"") | K34: =IFERROR(((BS_Timeline!K17+BS_Timeline!L17)/2)/IS_Flow!M15*91,"") | L34: =IFERROR(((BS_Timeline!L17+BS_Timeline!M17)/2)/IS_Flow!N15*92,"") | M34: =IFERROR(((BS_Timeline!M17+BS_Timeline!N17)/2)/IS_Flow!O15*92,"") | N34: =IFERROR(((BS_Timeline!N17+BS_Timeline!O17)/2)/IS_Flow!Q15*90,"") | O34: =IFERROR(((BS_Timeline!O17+BS_Timeline!P17)/2)/IS_Flow!R15*91,"") | P34: =IFERROR(((BS_Timeline!P17+BS_Timeline!Q17)/2)/IS_Flow!S15*92,"") | Q34: =IFERROR(((BS_Timeline!Q17+BS_Timeline!R17)/2)/IS_Flow!T15*92,"") | R34: =IFERROR(((BS_Timeline!R17+BS_Timeline!S17)/2)/IS_Flow!V15*90,"") | S34: =IFERROR(((BS_Timeline!S17+BS_Timeline!T17)/2)/IS_Flow!W15*91,"") | T34: =IFERROR(((BS_Timeline!T17+BS_Timeline!U17)/2)/IS_Flow!X15*92,"") | U34: =IFERROR(((BS_Timeline!U17+BS_Timeline!V17)/2)/IS_Flow!Y15*92,"")
A35: DIO (วัน) | B35: =IFERROR(((BS_Timeline!B18+BS_Timeline!C18)/2)/IS_Flow!B17*90,"") | C35: =IFERROR(((BS_Timeline!C18+BS_Timeline!D18)/2)/IS_Flow!C17*91,"") | D35: =IFERROR(((BS_Timeline!D18+BS_Timeline!E18)/2)/IS_Flow!D17*92,"") | E35: =IFERROR(((BS_Timeline!E18+BS_Timeline!F18)/2)/IS_Flow!E17*92,"") | F35: =IFERROR(((BS_Timeline!F18+BS_Timeline!G18)/2)/IS_Flow!G17*90,"") | G35: =IFERROR(((BS_Timeline!G18+BS_Timeline!H18)/2)/IS_Flow!H17*91,"") | H35: =IFERROR(((BS_Timeline!H18+BS_Timeline!I18)/2)/IS_Flow!I17*92,"") | I35: =IFERROR(((BS_Timeline!I18+BS_Timeline!J18)/2)/IS_Flow!J17*92,"") | J35: =IFERROR(((BS_Timeline!J18+BS_Timeline!K18)/2)/IS_Flow!L17*90,"") | K35: =IFERROR(((BS_Timeline!K18+BS_Timeline!L18)/2)/IS_Flow!M17*91,"") | L35: =IFERROR(((BS_Timeline!L18+BS_Timeline!M18)/2)/IS_Flow!N17*92,"") | M35: =IFERROR(((BS_Timeline!M18+BS_Timeline!N18)/2)/IS_Flow!O17*92,"") | N35: =IFERROR(((BS_Timeline!N18+BS_Timeline!O18)/2)/IS_Flow!Q17*90,"") | O35: =IFERROR(((BS_Timeline!O18+BS_Timeline!P18)/2)/IS_Flow!R17*91,"") | P35: =IFERROR(((BS_Timeline!P18+BS_Timeline!Q18)/2)/IS_Flow!S17*92,"") | Q35: =IFERROR(((BS_Timeline!Q18+BS_Timeline!R18)/2)/IS_Flow!T17*92,"") | R35: =IFERROR(((BS_Timeline!R18+BS_Timeline!S18)/2)/IS_Flow!V17*90,"") | S35: =IFERROR(((BS_Timeline!S18+BS_Timeline!T18)/2)/IS_Flow!W17*91,"") | T35: =IFERROR(((BS_Timeline!T18+BS_Timeline!U18)/2)/IS_Flow!X17*92,"") | U35: =IFERROR(((BS_Timeline!U18+BS_Timeline!V18)/2)/IS_Flow!Y17*92,"")
A36: DPO (วัน) | B36: =IFERROR(((BS_Timeline!B19+BS_Timeline!C19)/2)/IS_Flow!B17*90,"") | C36: =IFERROR(((BS_Timeline!C19+BS_Timeline!D19)/2)/IS_Flow!C17*91,"") | D36: =IFERROR(((BS_Timeline!D19+BS_Timeline!E19)/2)/IS_Flow!D17*92,"") | E36: =IFERROR(((BS_Timeline!E19+BS_Timeline!F19)/2)/IS_Flow!E17*92,"") | F36: =IFERROR(((BS_Timeline!F19+BS_Timeline!G19)/2)/IS_Flow!G17*90,"") | G36: =IFERROR(((BS_Timeline!G19+BS_Timeline!H19)/2)/IS_Flow!H17*91,"") | H36: =IFERROR(((BS_Timeline!H19+BS_Timeline!I19)/2)/IS_Flow!I17*92,"") | I36: =IFERROR(((BS_Timeline!I19+BS_Timeline!J19)/2)/IS_Flow!J17*92,"") | J36: =IFERROR(((BS_Timeline!J19+BS_Timeline!K19)/2)/IS_Flow!L17*90,"") | K36: =IFERROR(((BS_Timeline!K19+BS_Timeline!L19)/2)/IS_Flow!M17*91,"") | L36: =IFERROR(((BS_Timeline!L19+BS_Timeline!M19)/2)/IS_Flow!N17*92,"") | M36: =IFERROR(((BS_Timeline!M19+BS_Timeline!N19)/2)/IS_Flow!O17*92,"") | N36: =IFERROR(((BS_Timeline!N19+BS_Timeline!O19)/2)/IS_Flow!Q17*90,"") | O36: =IFERROR(((BS_Timeline!O19+BS_Timeline!P19)/2)/IS_Flow!R17*91,"") | P36: =IFERROR(((BS_Timeline!P19+BS_Timeline!Q19)/2)/IS_Flow!S17*92,"") | Q36: =IFERROR(((BS_Timeline!Q19+BS_Timeline!R19)/2)/IS_Flow!T17*92,"") | R36: =IFERROR(((BS_Timeline!R19+BS_Timeline!S19)/2)/IS_Flow!V17*90,"") | S36: =IFERROR(((BS_Timeline!S19+BS_Timeline!T19)/2)/IS_Flow!W17*91,"") | T36: =IFERROR(((BS_Timeline!T19+BS_Timeline!U19)/2)/IS_Flow!X17*92,"") | U36: =IFERROR(((BS_Timeline!U19+BS_Timeline!V19)/2)/IS_Flow!Y17*92,"")
A37: CCC (วัน) | B37: =IFERROR(B34+B35-B36,"") | C37: =IFERROR(C34+C35-C36,"") | D37: =IFERROR(D34+D35-D36,"") | E37: =IFERROR(E34+E35-E36,"") | F37: =IFERROR(F34+F35-F36,"") | G37: =IFERROR(G34+G35-G36,"") | H37: =IFERROR(H34+H35-H36,"") | I37: =IFERROR(I34+I35-I36,"") | ... U37: =IFERROR(U34+U35-U36,"")
A38: ROA รายไตรมาส (%) | B38: =IFERROR(IS_Flow!B18/((BS_Timeline!B20+BS_Timeline!C20)/2),"") | C38: =IFERROR(IS_Flow!C18/((BS_Timeline!C20+BS_Timeline!D20)/2),"") | D38: =IFERROR(IS_Flow!D18/((BS_Timeline!D20+BS_Timeline!E20)/2),"") | E38: =IFERROR(IS_Flow!E18/((BS_Timeline!E20+BS_Timeline!F20)/2),"") | F38: =IFERROR(IS_Flow!G18/((BS_Timeline!F20+BS_Timeline!G20)/2),"") | G38: =IFERROR(IS_Flow!H18/((BS_Timeline!G20+BS_Timeline!H20)/2),"") | H38: =IFERROR(IS_Flow!I18/((BS_Timeline!H20+BS_Timeline!I20)/2),"") | I38: =IFERROR(IS_Flow!J18/((BS_Timeline!I20+BS_Timeline!J20)/2),"") | J38: =IFERROR(IS_Flow!L18/((BS_Timeline!J20+BS_Timeline!K20)/2),"") | K38: =IFERROR(IS_Flow!M18/((BS_Timeline!K20+BS_Timeline!L20)/2),"") | L38: =IFERROR(IS_Flow!N18/((BS_Timeline!L20+BS_Timeline!M20)/2),"") | M38: =IFERROR(IS_Flow!O18/((BS_Timeline!M20+BS_Timeline!N20)/2),"") | N38: =IFERROR(IS_Flow!Q18/((BS_Timeline!N20+BS_Timeline!O20)/2),"") | O38: =IFERROR(IS_Flow!R18/((BS_Timeline!O20+BS_Timeline!P20)/2),"") | P38: =IFERROR(IS_Flow!S18/((BS_Timeline!P20+BS_Timeline!Q20)/2),"") | Q38: =IFERROR(IS_Flow!T18/((BS_Timeline!Q20+BS_Timeline!R20)/2),"") | R38: =IFERROR(IS_Flow!V18/((BS_Timeline!R20+BS_Timeline!S20)/2),"") | S38: =IFERROR(IS_Flow!W18/((BS_Timeline!S20+BS_Timeline!T20)/2),"") | T38: =IFERROR(IS_Flow!X18/((BS_Timeline!T20+BS_Timeline!U20)/2),"") | U38: =IFERROR(IS_Flow!Y18/((BS_Timeline!U20+BS_Timeline!V20)/2),"")
A39: ROE รายไตรมาส (%) | B39: =IFERROR(IS_Flow!B18/((BS_Timeline!B21+BS_Timeline!C21)/2),"") | C39: =IFERROR(IS_Flow!C18/((BS_Timeline!C21+BS_Timeline!D21)/2),"") | D39: =IFERROR(IS_Flow!D18/((BS_Timeline!D21+BS_Timeline!E21)/2),"") | E39: =IFERROR(IS_Flow!E18/((BS_Timeline!E21+BS_Timeline!F21)/2),"") | F39: =IFERROR(IS_Flow!G18/((BS_Timeline!F21+BS_Timeline!G21)/2),"") | G39: =IFERROR(IS_Flow!H18/((BS_Timeline!G21+BS_Timeline!H21)/2),"") | H39: =IFERROR(IS_Flow!I18/((BS_Timeline!H21+BS_Timeline!I21)/2),"") | I39: =IFERROR(IS_Flow!J18/((BS_Timeline!I21+BS_Timeline!J21)/2),"") | J39: =IFERROR(IS_Flow!L18/((BS_Timeline!J21+BS_Timeline!K21)/2),"") | K39: =IFERROR(IS_Flow!M18/((BS_Timeline!K21+BS_Timeline!L21)/2),"") | L39: =IFERROR(IS_Flow!N18/((BS_Timeline!L21+BS_Timeline!M21)/2),"") | M39: =IFERROR(IS_Flow!O18/((BS_Timeline!M21+BS_Timeline!N21)/2),"") | N39: =IFERROR(IS_Flow!Q18/((BS_Timeline!N21+BS_Timeline!O21)/2),"") | O39: =IFERROR(IS_Flow!R18/((BS_Timeline!O21+BS_Timeline!P21)/2),"") | P39: =IFERROR(IS_Flow!S18/((BS_Timeline!P21+BS_Timeline!Q21)/2),"") | Q39: =IFERROR(IS_Flow!T18/((BS_Timeline!Q21+BS_Timeline!R21)/2),"") | R39: =IFERROR(IS_Flow!V18/((BS_Timeline!R21+BS_Timeline!S21)/2),"") | S39: =IFERROR(IS_Flow!W18/((BS_Timeline!S21+BS_Timeline!T21)/2),"") | T39: =IFERROR(IS_Flow!X18/((BS_Timeline!T21+BS_Timeline!U21)/2),"") | U39: =IFERROR(IS_Flow!Y18/((BS_Timeline!U21+BS_Timeline!V21)/2),"")
A40: D/E (เท่า) | B40: =IFERROR(BS_Timeline!C22/BS_Timeline!C21,"") | C40: =IFERROR(BS_Timeline!D22/BS_Timeline!D21,"") | D40: =IFERROR(BS_Timeline!E22/BS_Timeline!E21,"") | E40: =IFERROR(BS_Timeline!F22/BS_Timeline!F21,"") | F40: =IFERROR(BS_Timeline!G22/BS_Timeline!G21,"") | G40: =IFERROR(BS_Timeline!H22/BS_Timeline!H21,"") | H40: =IFERROR(BS_Timeline!I22/BS_Timeline!I21,"") | I40: =IFERROR(BS_Timeline!J22/BS_Timeline!J21,"") | ... U40: =IFERROR(BS_Timeline!V22/BS_Timeline!V21,"")
...

Sheet IS_Flow
A1: รายการ (ล้านบาท, 3 เดือน) | B1: Q1/2564 | C1: Q2/2564 | D1: Q3/2564 | E1: Q4/2564 | F1: FY2564 | G1: Q1/2565 | H1: Q2/2565 | I1: Q3/2565 | J1: Q4/2565 | K1: FY2565 | L1: Q1/2566 | M1: Q2/2566 | N1: Q3/2566 | O1: Q4/2566 | P1: FY2566 | Q1: Q1/2567 | R1: Q2/2567 | S1: Q3/2567 | T1: Q4/2567 | U1: FY2567 | V1: Q1/2568 | W1: Q2/2568 | X1: Q3/2568 | Y1: Q4/2568 | Z1: FY2568
A2: ■ ASIA
A3: รายได้รวม | B3: 161.421 | C3: 143.655 | D3: 146.768 | E3: =F3-B3-C3-D3 | F3: 599.845 | G3: 173.164 | H3: 210.576 | I3: 255.119 | J3: =K3-G3-H3-I3 | K3: 924.299 | L3: 299.966 | M3: 289.335 | N3: 307.831 | O3: =P3-L3-M3-N3 | P3: 1188.482 | Q3: 316.06 | R3: 306.951 | S3: 326.359 | T3: =U3-Q3-R3-S3 | U3: 1275.109 | V3: 342.684 | W3: 306.205 | X3: 321.648 | Y3: =Z3-V3-W3-X3 | Z3: 1364.564
A4: รายได้อื่น | B4: 12.568 | C4: 13.539 | D4: 8.788 | E4: =F4-B4-C4-D4 | F4: 48.375 | G4: 10.123 | H4: 11.369 | I4: 12.28 | J4: =K4-G4-H4-I4 | K4: 45.181 | L4: 15.717 | M4: 16.357 | N4: 22.347 | O4: =P4-L4-M4-N4 | P4: 72.435 | Q4: 15.012 | R4: 19.732 | S4: 15.012 | T4: =U4-Q4-R4-S4 | U4: 77.119 | V4: 19.762 | W4: 19.916 | X4: 23.877 | Y4: =Z4-V4-W4-X4 | Z4: 80.027
A5: ต้นทุนขาย (จริง) | B5: 155.453 | C5: 150.548 | D5: 137.157 | E5: =F5-B5-C5-D5 | F5: 603.606 | G5: 161.775 | H5: 179.281 | I5: 201.105 | J5: =K5-G5-H5-I5 | K5: 747.973 | L5: 219.817 | M5: 220.397 | N5: 223.495 | O5: =P5-L5-M5-N5 | P5: 876.527 | Q5: 220.309 | R5: 222.275 | S5: 241.647 | T5: =U5-Q5-R5-S5 | U5: 921.247 | V5: 233.19 | W5: 233.988 | X5: 236.609 | Y5: =Z5-V5-W5-X5 | Z5: 942.602
A6: กำไรสุทธิ (รวม) | B6: -48.5 | C6: -58.89 | D6: -37.553 | E6: =F6-B6-C6-D6 | F6: -210.623 | G6: -49.978 | H6: -35.144 | I6: -25.28 | J6: =K6-G6-H6-I6 | K6: -112.271 | L6: -13.24 | M6: -5.875 | N6: 5.997 | O6: =P6-L6-M6-N6 | P6: -60.57 | Q6: 0.722 | R6: -4.117 | S6: -4.096 | T6: =U6-Q6-R6-S6 | U6: -5.596 | V6: 14.423 | W6: -14.973 | X6: -6.092 | Y6: =Z6-V6-W6-X6 | Z6: -3.355
A7: กำไรสุทธิ (ส่วนแม่) | B7: -48.531 | C7: -58.854 | D7: -36.74 | E7: =F7-B7-C7-D7 | F7: -209.093 | G7: -49.915 | H7: -35.074 | I7: -24.879 | J7: =K7-G7-H7-I7 | K7: -111.452 | L7: -11.584 | M7: -5.349 | N7: 6.344 | O7: =P7-L7-M7-N7 | P7: -54.265 | Q7: 1.637 | R7: -3.459 | S7: -3.001 | T7: =U7-Q7-R7-S7 | U7: -2.181 | V7: 14.963 | W7: -14.469 | X7: -5.466 | Y7: =Z7-V7-W7-X7 | Z7: -1.129
A8: ■ CENTEL
A9: รายได้รวม | B9: 2754.569 | C9: 2661.964 | D9: 2396.598 | E9: =F9-B9-C9-D9 | F9: 11528.506 | G9: 3851.608 | H9: 4296.949 | I9: 4527.85 | J9: =K9-G9-H9-I9 | K9: 18036.317 | L9: 5804.619 | M9: 5171.518 | N9: 5351.553 | O9: =P9-L9-M9-N9 | P9: 22261.37 | Q9: 6321.691 | R9: 5763.953 | S9: 5539.57 | T9: =U9-Q9-R9-S9 | U9: 23949.529 | V9: 6695.756 | W9: 5752.002 | X9: 5773.648 | Y9: =Z9-V9-W9-X9 | Z9: 25050.93
A10: รายได้อื่น | B10: 72.532 | C10: 264.614 | D10: 341.183 | E10: =F10-B10-C10-D10 | F10: 317.256 | G10: 170.493 | H10: 379.093 | I10: 384.698 | J10: =K10-G10-H10-I10 | K10: 534.308 | L10: 274.671 | M10: 495.957 | N10: 664.926 | O10: =P10-L10-M10-N10 | P10: 703.732 | Q10: 217.796 | R10: 674.042 | S10: 721.003 | T10: =U10-Q10-R10-S10 | U10: 900.661 | V10: 273.087 | W10: 578.369 | X10: 729.45 | Y10: =Z10-V10-W10-X10 | Z10: 1096.979
A11: ต้นทุนขาย (จริง) | B11: 1813.043 | C11: 1848.835 | D11: 1757.659 | E11: =F11-B11-C11-D11 | F11: 7613.439 | G11: 2285.245 | H11: 2518.558 | I11: 2669.11 | J11: =K11-G11-H11-I11 | K11: 10493.716 | L11: 3049.21 | M11: 3044.968 | N11: 3120.644 | O11: =P11-L11-M11-N11 | P11: 12710.76 | Q11: 3335.369 | R11: 3275.665 | S11: 3257.927 | T11: =U11-Q11-R11-S11 | U11: 13424.442 | V11: 3390.386 | W11: 3359.448 | X11: 3214.825 | Y11: =Z11-V11-W11-X11 | Z11: 13356.611
A12: กำไรสุทธิ (รวม) | B12: -480.758 | C12: -634.245 | D12: -832.299 | E12: =F12-B12-C12-D12 | F12: -1757.4 | G12: -23.161 | H12: 18.661 | I12: -90.175 | J12: =K12-G12-H12-I12 | K12: 414.432 | L12: 680.935 | M12: 99.086 | N12: 53.971 | O12: =P12-L12-M12-N12 | P12: 1256.213 | Q12: 785.318 | R12: 124.139 | S12: 150.556 | T12: =U12-Q12-R12-S12 | U12: 1696.274 | V12: 761.578 | W12: 85.859 | X12: 142.249 | Y12: =Z12-V12-W12-X12 | Z12: 1964.146
A13: กำไรสุทธิ (ส่วนแม่) | B13: -475.727 | C13: -606.493 | D13: -803.319 | E13: =F13-B13-C13-D13 | F13: -1733.207 | G13: -43.692 | H13: 22.063 | I13: -78.062 | J13: =K13-G13-H13-I13 | K13: 398.082 | L13: 629.08 | M13: 120.632 | N13: 73.772 | O13: =P13-L13-M13-N13 | P13: 1248.096 | Q13: 755.314 | R13: 167.522 | S13: 163.096 | T13: =U13-Q13-R13-S13 | U13: 1752.985 | V13: 747.845 | W13: 110.343 | X13: 160.361 | Y13: =Z13-V13-W13-X13 | Z13: 1992.902
A14: ■ DUSIT
A15: รายได้รวม | B15: 666.595 | C15: 632.841 | D15: 830.933 | E15: =F15-B15-C15-D15 | F15: 3427.418 | G15: 1112.198 | H15: 1033.032 | I15: 1257.963 | J15: =K15-G15-H15-I15 | K15: 5104.079 | L15: 1688.672 | M15: 1348.349 | N15: 1415.732 | O15: =P15-L15-M15-N15 | P15: 6361.84 | Q15: 2105.334 | R15: 1561.562 | S15: 1441.319 | T15: =U15-Q15-R15-S15 | U15: 11080.275 | V15: 2344.842 | W15: 1709.084 | X15: 1751.875 | Y15: =Z15-V15-W15-X15 | Z15: 8923.997
A16: รายได้อื่น | B16: 111.981 | C16: 95.873 | D16: 83.685 | E16: =F16-B16-C16-D16 | F16: 415.078 | G16: 78.605 | H16: 143.172 | I16: 244.914 | J16: =K16-G16-H16-I16 | K16: 613.544 | L16: 204.263 | M16: 212.948 | N16: 221.776 | O16: =P16-L16-M16-N16 | P16: 881.649 | Q16: 279.83 | R16: 170.769 | S16: 168.247 | T16: =U16-Q16-R16-S16 | U16: 905.859 | V16: 218.828 | W16: 213.603 | X16: 218.099 | Y16: =Z16-V16-W16-X16 | Z16: 1013.082
A17: ต้นทุนขาย (จริง) | B17: 508.519 | C17: 402.241 | D17: 541.069 | E17: =F17-B17-C17-D17 | F17: 2043.818 | G17: 618.443 | H17: 646.479 | I17: 721.753 | J17: =K17-G17-H17-I17 | K17: 2851.015 | L17: 897.178 | M17: 772.196 | N17: 843.255 | O17: =P17-L17-M17-N17 | P17: 3612.823 | Q17: 1105.459 | R17: 917.935 | S17: 888.69 | T17: =U17-Q17-R17-S17 | U17: 7228.101 | V17: 1355.983 | W17: 1068.566 | X17: 1139.186 | Y17: =Z17-V17-W17-X17 | Z17: 5378.316
A18: กำไรสุทธิ (รวม) | B18: 55.029 | C18: -407.99 | D18: -304.231 | E18: =F18-B18-C18-D18 | F18: -1023.973 | G18: -145.62 | H18: -275.736 | I18: -183.952 | J18: =K18-G18-H18-I18 | K18: -547.147 | L18: 11.324 | M18: -193.65 | N18: -253.504 | O18: =P18-L18-M18-N18 | P18: -584.066 | Q18: 126.005 | R18: -136.814 | S18: -571.999 | T18: =U18-Q18-R18-S18 | U18: -151.367 | V18: 36.15 | W18: -324.379 | X18: -422.865 | Y18: =Z18-V18-W18-X18 | Z18: -470.835
A19: กำไรสุทธิ (ส่วนแม่) | B19: 73.786 | C19: -375.562 | D19: -301.809 | E19: =F19-B19-C19-D19 | F19: -944.997 | G19: -128.665 | H19: -257.749 | I19: -161.23 | J19: =K19-G19-H19-I19 | K19: -501.462 | L19: 8.628 | M19: -185.949 | N19: -246.966 | O19: =P19-L19-M19-N19 | P19: -569.82 | Q19: 122.117 | R19: -130.848 | S19: -538.078 | T19: =U19-Q19-R19-S19 | U19: -236.765 | V19: 47.856 | W19: -290.72 | X19: -383.733 | Y19: =Z19-V19-W19-X19 | Z19: -453.313
A20: ■ ERW
A21: รายได้รวม | B21: 390.059 | C21: 269.132 | D21: 253.762 | E21: =F21-B21-C21-D21 | F21: 1641.258 | G21: 646.094 | H21: 1006.085 | I21: 1289.39 | J21: =K21-G21-H21-I21 | K21: 4717.288 | L21: 1774.625 | M21: 1641.935 | N21: 1742.8 | O21: =P21-L21-M21-N21 | P21: 7046.29 | Q21: 2119.357 | R21: 1843.268 | S21: 1856.024 | T21: =U21-Q21-R21-S21 | U21: 8053.926 | V21: 2135.663 | W21: 1753.339 | X21: 1788.638 | Y21: =Z21-V21-W21-X21 | Z21: 7937.392
A22: รายได้อื่น | B22: 16.644 | C22: 23.294 | D22: 70.719 | E22: =F22-B22-C22-D22 | F22: 77.118 | G22: 12.487 | H22: 69.651 | I22: 49.647 | J22: =K22-G22-H22-I22 | K22: 86.023 | L22: 25.444 | M22: 52.552 | N22: 48.472 | O22: =P22-L22-M22-N22 | P22: 52.98 | Q22: 14.968 | R22: 28.872 | S22: 33.976 | T22: =U22-Q22-R22-S22 | U22: 45.19 | V22: 6.865 | W22: 7.545 | X22: 23.796 | Y22: =Z22-V22-W22-X22 | Z22: 25.178
A23: ต้นทุนขาย (จริง) | B23: 315.026 | C23: 284.888 | D23: 286.682 | E23: =F23-B23-C23-D23 | F23: 1284.16 | G23: 404.82 | H23: 519.988 | I23: 607.211 | J23: =K23-G23-H23-I23 | K23: 2282.152 | L23: 775.229 | M23: 726.693 | N23: 757.077 | O23: =P23-L23-M23-N23 | P23: 3034.518 | Q23: 793.662 | R23: 809.742 | S23: 812.235 | T23: =U23-Q23-R23-S23 | U23: 3275.985 | V23: 836.589 | W23: 792.994 | X23: 801.101 | Y23: =Z23-V23-W23-X23 | Z23: 3265.028
A24: กำไรสุทธิ (รวม) | B24: -512.877 | C24: -716.788 | D24: -667.617 | E24: =F24-B24-C24-D24 | F24: -2155.372 | G24: -324.862 | H24: -143.041 | I24: -5.353 | J24: =K24-G24-H24-I24 | K24: -213.062 | L24: 237.391 | M24: 143.879 | N24: 155.228 | O24: =P24-L24-M24-N24 | P24: 759.877 | Q24: 428.404 | R24: 365.506 | S24: 124.49 | T24: =U24-Q24-R24-S24 | U24: 1312.506 | V24: 362.736 | W24: 69.78 | X24: 59.797 | Y24: =Z24-V24-W24-X24 | Z24: 904.756
A25: กำไรสุทธิ (ส่วนแม่) | B25: -491.944 | C25: -689.778 | D25: -622.789 | E25: =F25-B25-C25-D25 | F25: -2050.217 | G25: -313.095 | H25: -139.108 | I25: -11.52 | J25: =K25-G25-H25-I25 | K25: -224.19 | L25: 238.561 | M25: 141.969 | N25: 148.293 | O25: =P25-L25-M25-N25 | P25: 742.656 | Q25: 416.953 | R25: 361.434 | S25: 124.53 | T25: =U25-Q25-R25-S25 | U25: 1280.743 | V25: 345.382 | W25: 63.009 | X25: 56.6 | Y25: =Z25-V25-W25-X25 | Z25: 838.085
A26: ■ MANRIN
A27: รายได้รวม | B27: 9.414 | C27: 4.916 | D27: 2.01 | E27: 9.366 | F27: =B27+C27+D27+E27 | G27: 13.143 | H27: 32.014 | I27: 51.026 | J27: 71.111 | K27: =G27+H27+I27+J27 | L27: 76.04 | M27: 68.615 | N27: 90.678 | O27: 89.961 | P27: =L27+M27+N27+O27 | Q27: 93.403 | R27: 80.831 | S27: 99.856 | T27: =U27-Q27-R27-S27 | U27: 376.742 | V27: 97.881 | W27: 75.445 | X27: 95.086 | Y27: =Z27-V27-W27-X27 | Z27: 363.247
A28: รายได้อื่น | B28: 0.097 | C28: 1.16 | D28: 0.404 | E28: 1.277 | F28: =B28+C28+D28+E28 | G28: 0.435 | H28: 1.8 | I28: 0.271 | J28: 0.085 | K28: =G28+H28+I28+J28 | L28: 0.302 | M28: 0.279 | N28: 0.416 | O28: 0.343 | P28: =L28+M28+N28+O28 | Q28: 0.262 | R28: 0.338 | S28: 0.239 | T28: =U28-Q28-R28-S28 | U28: 1.161 | V28: 0.176 | W28: 0.532 | X28: 0.196 | Y28: =Z28-V28-W28-X28 | Z28: 1.015
A29: ต้นทุนขาย (จริง) | B29: 24.135 | C29: 22.547 | D29: 20.772 | E29: 24.077 | F29: =B29+C29+D29+E29 | G29: 27.44 | H29: 34.428 | I29: 42.762 | J29: 48.739 | K29: =G29+H29+I29+J29 | L29: 51.265 | M29: 46.198 | N29: 55.052 | O29: 52.535 | P29: =L29+M29+N29+O29 | Q29: 50.823 | R29: 46.844 | S29: 55.598 | T29: =U29-Q29-R29-S29 | U29: 210.68 | V29: 53.115 | W29: 48.048 | X29: 57.538 | Y29: =Z29-V29-W29-X29 | Z29: 213.736
A30: กำไรสุทธิ (รวม) | B30: -16.489 | C30: -22.583 | D30: 12.558 | E30: -22.328 | F30: =B30+C30+D30+E30 | G30: -30.293 | H30: -12.05 | I30: -4.503 | J30: 6.961 | K30: =G30+H30+I30+J30 | L30: 6.844 | M30: 1.195 | N30: 15.371 | O30: 11.273 | P30: =L30+M30+N30+O30 | Q30: 13.794 | R30: 6.882 | S30: 18.194 | T30: =U30-Q30-R30-S30 | U30: 50.821 | V30: 14.114 | W30: 3.665 | X30: 11.84 | Y30: =Z30-V30-W30-X30 | Z30: 39.818
A31: กำไรสุทธิ (ส่วนแม่) | B31: -16.489 | C31: -22.583 | D31: 12.558 | E31: -22.328 | F31: =B31+C31+D31+E31 | G31: -30.293 | H31: -12.05 | I31: -4.503 | J31: 6.961 | K31: =G31+H31+I31+J31 | L31: 6.844 | M31: 1.195 | N31: 15.371 | O31: 11.273 | P31: =L31+M31+N31+O31 | Q31: 13.794 | R31: 6.882 | S31: 18.194 | T31: =U31-Q31-R31-S31 | U31: 50.821 | V31: 14.114 | W31: 3.665 | X31: 11.84 | Y31: =Z31-V31-W31-X31 | Z31: 39.818
A32: ■ MINT
A33: รายได้รวม | B33: 12653.858 | C33: 15840.486 | D33: 20789.337 | E33: =F33-B33-C33-D33 | F33: 76211.261 | G33: 20672.252 | H33: 32348.359 | I33: 35153.927 | J33: =K33-G33-H33-I33 | K33: 124205.85 | L33: 32229.34 | M33: 40588.347 | N33: 39840.815 | O33: =P33-L33-M33-N33 | P33: 153049.24 | Q33: 37818.351 | R33: 44303.008 | S33: 41612.614 | T33: =U33-Q33-R33-S33 | U33: 165362.27 | V33: 37267.312 | W33: 43497.069 | X33: 41174.584 | Y33: =Z33-V33-W33-X33 | Z33: 165804.71
A34: รายได้อื่น | B34: 469.091 | C34: 1997.136 | D34: 1213.841 | E34: =F34-B34-C34-D34 | F34: 6096.415 | G34: 832.631 | H34: 720.23 | I34: 985.7 | J34: =K34-G34-H34-I34 | K34: 3411.985 | L34: 694.83 | M34: 487.442 | N34: 563.386 | O34: =P34-L34-M34-N34 | P34: 2344.767 | Q34: 950.347 | R34: 257.577 | S34: 693.591 | T34: =U34-Q34-R34-S34 | U34: 2764.749 | V34: 1481.442 | W34: 1105.297 | X34: 625.543 | Y34: =Z34-V34-W34-X34 | Z34: 4275.181
A35: ต้นทุนขาย (จริง) | B35: 8670.877 | C35: 9770.642 | D35: 11835.953 | E35: =F35-B35-C35-D35 | F35: 42471.697 | G35: 13113.487 | H35: 16080.254 | I35: 17222.59 | J35: =K35-G35-H35-I35 | K35: 63827.792 | L35: 17326.308 | M35: 19634.453 | N35: 19633.64 | O35: =P35-L35-M35-N35 | P35: 78150.469 | Q35: 20253.5 | R35: 22584.012 | S35: 21452.758 | T35: =U35-Q35-R35-S35 | U35: 85910.362 | V35: 20008.898 | W35: 22101.435 | X35: 21956.753 | Y35: =Z35-V35-W35-X35 | Z35: 86221.785
A36: กำไรสุทธิ (รวม) | B36: -7798.673 | C36: -4188.238 | D36: -551.893 | E36: =F36-B36-C36-D36 | F36: -14175.37 | G36: -4067.712 | H36: 1701.487 | I36: 4775.446 | J36: =K36-G36-H36-I36 | K36: 4522.68 | L36: -940.597 | M36: 3490.163 | N36: 2323.736 | O36: =P36-L36-M36-N36 | P36: 6087.974 | Q36: 1288.472 | R36: 3031.497 | S36: 361.424 | T36: =U36-Q36-R36-S36 | U36: 8601.924 | V36: 611.516 | W36: 3322.548 | X36: 2667.974 | Y36: =Z36-V36-W36-X36 | Z36: 9839.333
A37: กำไรสุทธิ (ส่วนแม่) | B37: -7249.723 | C37: -3923.912 | D37: -435.558 | E37: =F37-B37-C37-D37 | F37: -13166.508 | G37: -3793.733 | H37: 1561.499 | I37: 4607.942 | J37: =K37-G37-H37-I37 | K37: 4286.373 | L37: -975.899 | M37: 3255.129 | N37: 2143.757 | O37: =P37-L37-M37-N37 | P37: 5407.055 | Q37: 1146.079 | R37: 2823.217 | S37: 149.396 | T37: =U37-Q37-R37-S37 | U37: 7750.222 | V37: 416.865 | W37: 3085.506 | X37: 2553.479 | Y37: =Z37-V37-W37-X37 | Z37: 9009.342
A38: ■ OHTL
A39: รายได้รวม | B39: 150.921 | C39: 84.16 | D39: 106.611 | E39: =F39-B39-C39-D39 | F39: 562.367 | G39: 253.984 | H39: 335.731 | I39: 479.84 | J39: =K39-G39-H39-I39 | K39: 1931.398 | L39: 687.622 | M39: 546.382 | N39: 574.546 | O39: =P39-L39-M39-N39 | P39: 2520.311 | Q39: 773.141 | R39: 525.654 | S39: 621.464 | T39: =U39-Q39-R39-S39 | U39: 2705.661 | V39: 789.301 | W39: 433.486 | X39: 478.331 | Y39: =Z39-V39-W39-X39 | Z39: 2524.941
A40: รายได้อื่น | B40: 0.201 | C40: 0.022 | D40: 0.062 | E40: =F40-B40-C40-D40 | F40: 0.369 | G40: 1.705 | H40: 0.296 | I40: 0.333 | J40: =K40-G40-H40-I40 | K40: 3.627 | L40: 1.069 | M40: 0.71 | N40: 0.604 | O40: =P40-L40-M40-N40 | P40: 3.488 | Q40: 1.18 | R40: 0.747 | S40: 0.763 | T40: =U40-Q40-R40-S40 | U40: 3.875 | V40: 0.857 | W40: 1.455 | X40: 0.607 | Y40: =Z40-V40-W40-X40 | Z40: 2.68
...

Sheet BS_Timeline
A1: รายการ (ยอดคงเหลือ, ล้านบาท) | B1: 31-Dec-2563 | C1: 31-Mar-2564 | D1: 30-Jun-2564 | E1: 30-Sep-2564 | F1: 31-Dec-2564 | G1: 31-Mar-2565 | H1: 30-Jun-2565 | I1: 30-Sep-2565 | J1: 31-Dec-2565 | K1: 31-Mar-2566 | L1: 30-Jun-2566 | M1: 30-Sep-2566 | N1: 31-Dec-2566 | O1: 31-Mar-2567 | P1: 30-Jun-2567 | Q1: 30-Sep-2567 | R1: 31-Dec-2567 | S1: 31-Mar-2568 | T1: 30-Jun-2568 | U1: 30-Sep-2568 | V1: 31-Dec-2568
A2: ■ ASIA
A3: ลูกหนี้การค้า | B3: 136.25 | C3: 145.444 | D3: 139.641 | E3: 198.409 | F3: 134.447 | G3: 140.663 | H3: 142.238 | I3: 127.504 | J3: 137.68 | K3: 150.621 | L3: 143.885 | M3: 149.662 | N3: 122.044 | O3: 125.417 | P3: 115.971 | Q3: 105.384 | R3: 87.279 | S3: 83.364 | T3: 80.907 | U3: 89.843 | V3: 90.573
A4: สินค้าคงเหลือ | B4: 40.331 | C4: 39.374 | D4: 39.459 | E4: 39.702 | F4: 39.693 | G4: 39.429 | H4: 39.954 | I4: 39.43 | J4: 40.001 | K4: 40.924 | L4: 41.095 | M4: 42.135 | N4: 43.539 | O4: 43.141 | P4: 43.78 | Q4: 44.865 | R4: 46.247 | S4: 45.81 | T4: 45.767 | U4: 45.987 | V4: 46.002
A5: เจ้าหนี้การค้า | B5: 116.615 | C5: 103.557 | D5: 86.577 | E5: 92.384 | F5: 82.438 | G5: 82.773 | H5: 100.259 | I5: 109.055 | J5: 116.107 | K5: 125.439 | L5: 118.84 | M5: 118.148 | N5: 118.752 | O5: 123.558 | P5: 123.974 | Q5: 122.209 | R5: 140.797 | S5: 122.033 | T5: 118.6 | U5: 119.99 | V5: 150.322
A6: สินทรัพย์รวม | B6: 9569.274 | C6: 9453.576 | D6: 9433.053 | E6: 9416.727 | F6: 10500.936 | G6: 10401.72 | H6: 10389.057 | I6: 10415.012 | J6: 10456.552 | K6: 10324.99 | L6: 10277.756 | M6: 10250.041 | N6: 10212.295 | O6: 10195.015 | P6: 10337.145 | Q6: 10147.093 | R6: 10140.751 | S6: 10218.289 | T6: 10013.388 | U6: 9975.582 | V6: 10336.316
